Workbook
Name Cost_Centers: OFFSET([1]DataSheet!$N$2,,,COUNTA([1]DataSheet!$N$2:$N$10000))
Name CostCenter_Description: OFFSET([1]DataSheet!$M$2,,,COUNTA([1]DataSheet!$M$2:$M$10000))
Name Locations: OFFSET([2]DataSheet!$D$2,,,COUNTA([2]DataSheet!$D$2:$D$1000))
Name User_IDs: OFFSET([2]DataSheet!$A$2,,,COUNTA([2]DataSheet!$A$2:$A$4916))
Name User_Name: OFFSET([2]DataSheet!$B$2,,,COUNTA([2]DataSheet!$B$2:$B$4916))

Sheet Employee Database
A1: Employee ID | B1: Employee Name
A2: 33332 | B2: Usman
A3: 48748 | B3: Asghar Ali
A4: 49709 | B4: Mehmood Ahmed
A5: 50134 | B5: Asif Abbas
A6: 50266 | B6: Riaz
A7: 50273 | B7: Waseem
A8: 50313 | B8: Waseem Raza
A9: 50314 | B9: Hussnain Ashfaq
A10: 50315 | B10: Hafiz Fahad Bhatti
A11: 50524 | B11: Allah Rakha
A12: 50648 | B12: Shahzaib
A13: 50921 | B13: Raza Ali
... A69: 76412 | B69: Zubair Abbas

Sheet Summary
E3: Cash Sales | P3: Credit Sales | U3: Total Sales
B4: Date | C4: Day | E4: 1st | F4: 2nd | G4: 3rd | H4: 4th | I4: Closing | K4: Sum of Cash | L4: X-Tape | N4: Day Wise Shortage | P4: POS Cr.Sale | Q4: Settle Cr.Sale | S4: Day Wise Shortage | U4: Total Sales | X4: 1st | Y4: 2nd | Z4: 3rd | AA4: 4th | AB4: Close | AD4: X-Tape | AF4: POS Cr.Sale | AG4: Settle Cr.Sale
B5: 1 | C5: 2 | D5: 3 | E5: 4 | F5: 5 | G5: 6 | H5: 7 | I5: 8 | J5: 9 | K5: 10 | L5: 11 | M5: 12 | N5: 13 | O5: 14 | P5: 15 | Q5: 16 | R5: 17 | S5: 18 | T5: 19 | U5: 20
B6: 46204 | C6: =TEXT(B6,"ddd") -> Wed | E6: ='1'!F35 -> 2500500 | F6: ='1'!J35 -> 4301500 | G6: ='1'!N35 -> 0 | H6: ='1'!R35 -> 0 | I6: ='1'!AD35 -> 75905 | K6: =SUM(E6:I6) -> 6877905 | L6: ='1'!AE35 -> 6876713 | N6: =+K6-L6 -> 1192 | P6: ='1'!AI35 -> 16028027 | Q6: ='1'!AJ35 -> 16028017 | S6: =+P6-Q6 -> 10.73 | U6: =+K6+Q6 -> 22905922
B7: =+B6+1 -> 46205 | C7: =TEXT(B7,"ddd") -> Thu | E7: ='2'!F35 -> 2832500 | F7: ='2'!J35 -> 4698500 | G7: ='2'!N35 -> 0 | H7: ='2'!R35 -> 0 | I7: ='2'!AD35 -> 67350 | K7: =SUM(E7:I7) -> 7598350 | L7: ='2'!AE35 -> 7585015.3 | N7: =+K7-L7 -> 13334.68 | P7: ='2'!AI35 -> 14051289 | Q7: ='2'!AJ35 -> 14037725 | S7: =+P7-Q7 -> 13564.31 | U7: =+K7+Q7 -> 21636075
B8: =+B7+1 -> 46206 | C8: =TEXT(B8,"ddd") -> Fri | E8: ='3'!F36 -> 2678500 | F8: ='3'!J36 -> 4670000 | G8: ='3'!N36 -> 0 | H8: ='3'!R36 -> 0 | I8: ='3'!AD36 -> 83340 | K8: =SUM(E8:I8) -> 7431840 | N8: =+K8-L8 -> 7431840 | S8: =+P8-Q8 -> 0 | U8: =+K8+Q8 -> 7431840
B9: =+B8+1 -> 46207 | C9: =TEXT(B9,"ddd") -> Sat | K9: =SUM(E9:I9) -> 0 | N9: =+K9-L9 -> 0 | S9: =+P9-Q9 -> 0 | U9: =+K9+Q9 -> 0
B10: =+B9+1 -> 46208 | C10: =TEXT(B10,"ddd") -> Sun | K10: =SUM(E10:I10) -> 0 | N10: =+K10-L10 -> 0 | S10: =+P10-Q10 -> 0 | U10: =+K10+Q10 -> 0
B11: =+B10+1 -> 46209 | C11: =TEXT(B11,"ddd") -> Mon | K11: =SUM(E11:I11) -> 0 | N11: =+K11-L11 -> 0 | S11: =+P11-Q11 -> 0 | U11: =+K11+Q11 -> 0
B12: =+B11+1 -> 46210 | C12: =TEXT(B12,"ddd") -> Tue | K12: =SUM(E12:I12) -> 0 | N12: =+K12-L12 -> 0 | S12: =+P12-Q12 -> 0 | U12: =+K12+Q12 -> 0
B13: =+B12+1 -> 46211 | C13: =TEXT(B13,"ddd") -> Wed | K13: =SUM(E13:I13) -> 0 | N13: =+K13-L13 -> 0 | S13: =+P13-Q13 -> 0 | U13: =+K13+Q13 -> 0
B14: =+B13+1 -> 46212 | C14: =TEXT(B14,"ddd") -> Thu | K14: =SUM(E14:I14) -> 0 | N14: =+K14-L14 -> 0 | S14: =+P14-Q14 -> 0 | U14: =+K14+Q14 -> 0
B15: =+B14+1 -> 46213 | C15: =TEXT(B15,"ddd") -> Fri | K15: =SUM(E15:I15) -> 0 | N15: =+K15-L15 -> 0 | S15: =+P15-Q15 -> 0 | U15: =+K15+Q15 -> 0 | X15: ='10'!J58 | Y15: ='10'!T58 | Z15: ='10'!AD58 | AA15: ='10'!AN58 | AB15: ='10'!BO58 | AD15: ='10'!BS58 | AF15: ='10'!CD58 | AG15: ='10'!CH58
B16: =+B15+1 -> 46214 | C16: =TEXT(B16,"ddd") -> Sat | K16: =SUM(E16:I16) -> 0 | N16: =+K16-L16 -> 0 | S16: =+P16-Q16 -> 0 | U16: =+K16+Q16 -> 0 | X16: ='11'!J58 | Y16: ='11'!T58 | Z16: ='11'!AD58 | AA16: ='11'!AN58 | AB16: ='11'!BO58 | AD16: ='11'!BS58 | AF16: ='11'!CD58 | AG16: ='11'!CH58
B17: =+B16+1 -> 46215 | C17: =TEXT(B17,"ddd") -> Sun | K17: =SUM(E17:I17) -> 0 | N17: =+K17-L17 -> 0 | S17: =+P17-Q17 -> 0 | U17: =+K17+Q17 -> 0 | X17: ='12'!J58 | Y17: ='12'!T58 | Z17: ='12'!AD58 | AA17: ='12'!AN58 | AB17: ='12'!BO58 | AD17: ='12'!BS58 | AF17: ='12'!CD58 | AG17: ='12'!CH58
B18: =+B17+1 -> 46216 | C18: =TEXT(B18,"ddd") -> Mon | K18: =SUM(E18:I18) -> 0 | N18: =+K18-L18 -> 0 | S18: =+P18-Q18 -> 0 | U18: =+K18+Q18 -> 0 | X18: ='13'!J58 | Y18: ='13'!T58 | Z18: ='13'!AD58 | AA18: ='13'!AN58 | AB18: ='13'!BO58 | AD18: ='13'!BS58 | AF18: ='13'!CD58 | AG18: ='13'!CH58
B19: =+B18+1 -> 46217 | C19: =TEXT(B19,"ddd") -> Tue | K19: =SUM(E19:I19) -> 0 | N19: =+K19-L19 -> 0 | S19: =+P19-Q19 -> 0 | U19: =+K19+Q19 -> 0 | X19: ='14'!J58 | Y19: ='14'!T58 | Z19: ='14'!AD58 | AA19: ='14'!AN58 | AB19: ='14'!BO58 | AD19: ='14'!BS58 | AF19: ='14'!CD58 | AG19: ='14'!CH58
B20: =+B19+1 -> 46218 | C20: =TEXT(B20,"ddd") -> Wed | K20: =SUM(E20:I20) -> 0 | N20: =+K20-L20 -> 0 | S20: =+P20-Q20 -> 0 | U20: =+K20+Q20 -> 0 | X20: ='15'!J58 | Y20: ='15'!T58 | Z20: ='15'!AD58 | AA20: ='15'!AN58 | AB20: ='15'!BO58 | AD20: ='15'!BS58 | AF20: ='15'!CD58 | AG20: ='15'!CH58
B21: =+B20+1 -> 46219 | C21: =TEXT(B21,"ddd") -> Thu | K21: =SUM(E21:I21) -> 0 | N21: =+K21-L21 -> 0 | S21: =+P21-Q21 -> 0 | U21: =+K21+Q21 -> 0 | X21: ='16'!J58 | Y21: ='16'!T58 | Z21: ='16'!AD58 | AA21: ='16'!AN58 | AB21: ='16'!BO58 | AD21: ='16'!BS58 | AF21: ='16'!CD58 | AG21: ='16'!CH58
B22: =+B21+1 -> 46220 | C22: =TEXT(B22,"ddd") -> Fri | K22: =SUM(E22:I22) -> 0 | N22: =+K22-L22 -> 0 | S22: =+P22-Q22 -> 0 | U22: =+K22+Q22 -> 0 | X22: ='17'!J58 | Y22: ='17'!T58 | Z22: ='17'!AD58 | AA22: ='17'!AN58 | AB22: ='17'!BO58 | AD22: ='17'!BS58 | AF22: ='17'!CD58 | AG22: ='17'!CH58
B23: =+B22+1 -> 46221 | C23: =TEXT(B23,"ddd") -> Sat | K23: =SUM(E23:I23) -> 0 | N23: =+K23-L23 -> 0 | S23: =+P23-Q23 -> 0 | U23: =+K23+Q23 -> 0 | X23: ='18'!J58 | Y23: ='18'!T58 | Z23: ='18'!AD58 | AA23: ='18'!AN58 | AB23: ='18'!BO58 | AD23: ='18'!BS58 | AF23: ='18'!CD58 | AG23: ='18'!CH58
B24: =+B23+1 -> 46222 | C24: =TEXT(B24,"ddd") -> Sun | K24: =SUM(E24:I24) -> 0 | N24: =+K24-L24 -> 0 | S24: =+P24-Q24 -> 0 | U24: =+K24+Q24 -> 0 | X24: ='19'!J58 | Y24: ='19'!T58 | Z24: ='19'!AD58 | AA24: ='19'!AN58 | AB24: ='19'!BO58 | AD24: ='19'!BS58 | AF24: ='19'!CD58 | AG24: ='19'!CH58
B25: =+B24+1 -> 46223 | C25: =TEXT(B25,"ddd") -> Mon | K25: =SUM(E25:I25) -> 0 | N25: =+K25-L25 -> 0 | S25: =+P25-Q25 -> 0 | U25: =+K25+Q25 -> 0 | X25: ='20'!J58 | Y25: ='20'!T58 | Z25: ='20'!AD58 | AA25: ='20'!AN58 | AB25: ='20'!BO58 | AD25: ='20'!BS58 | AF25: ='20'!CD58 | AG25: ='20'!CH58
B26: =+B25+1 -> 46224 | C26: =TEXT(B26,"ddd") -> Tue | K26: =SUM(E26:I26) -> 0 | N26: =+K26-L26 -> 0 | S26: =+P26-Q26 -> 0 | U26: =+K26+Q26 -> 0 | X26: ='21'!J58 | Y26: ='21'!T58 | Z26: ='21'!AD58 | AA26: ='21'!AN58 | AB26: ='21'!BO58 | AD26: ='21'!BS58 | AF26: ='21'!CD58 | AG26: ='21'!CH58
... B36: =+B35+1 -> 46234 | C36: =TEXT(B36,"ddd") -> Fri | K36: =SUM(E36:I36) -> 0 | N36: =+K36-L36 -> 0 | S36: =+P36-Q36 -> 0 | U36: =+K36+Q36 -> 0 | X36: ='31'!J58 | Y36: ='31'!T58 | Z36: ='31'!AD58 | AA36: ='31'!AN58 | AB36: ='31'!BO58 | AD36: ='31'!BS58 | AF36: ='31'!CD58 | AG36: ='31'!CH58
E37: =SUM(E6:E36) -> 8011500 | F37: =SUM(F6:F36) -> 13670000 | G37: =SUM(G6:G36) -> 0 | H37: =SUM(H6:H36) -> 0 | I37: =SUM(I6:I36) -> 226595 | K37: =SUM(K6:K36) -> 21908095 | L37: =SUM(L6:L36) -> 14461728 | N37: =SUM(N6:N36) -> 7446366.7 | P37: =SUM(P6:P36) -> 30079316 | Q37: =SUM(Q6:Q36) -> 30065741 | S37: =SUM(S6:S36) -> 13575.04 | U37: =SUM(U6:U36) -> 51973836

Sheet 1
A1: Daily Cash Collection - Lahore-4
A2: 46204
A3: Employee Details | C3: 1st Collection | G3: 2nd Collection | K3: 3rd Collection | O3: 4th Collection | S3: Fifth Collection (Closing Cash) | AD3: Closing | AH3: Settlemnet Report
A4: Emp ID | B4: Employee Name | C4: 5000 | D4: 1000 | E4: 500 | F4: Total | G4: 5000 | H4: 1000 | I4: 500 | J4: Total | K4: 5000 | L4: 1000 | M4: 500 | N4: Total | O4: 5000 | P4: 1000 | Q4: 500 | R4: Total | S4: 5000 | T4: 1000 | U4: 500 | V4: 100 | W4: 75 | X4: 50 | Y4: 20 | Z4: 10 | AA4: 5 | AB4: 2 | AC4: 1 | AD4: Total Closing Cash | AE4: System Total Sale | AF4: Collection Difference | AG4: Audit Status | AH4: Remarks | AI4: ivend Settle (POS) | AJ4: Settlement Report (Bank) | AK4: Card Difference | AL4: Card Status | AM4: Remaks
A5: 68107 | B5: =IF(A5="","",VLOOKUP(A5,'Employee Database'!A:B,2,FALSE)) -> M Harris | C5: 22 | D5: 96 | E5: 3 | F5: =IF(COUNT(C5:E5)=0,0,SUMPRODUCT({5000,1000,500},C5:E5)) -> 207500 | J5: =IF(COUNT(G5:I5)=0,0,SUMPRODUCT({5000,1000,500},G5:I5)) -> 0 | N5: =IF(COUNT(K5:M5)=0,0,SUMPRODUCT({5000,1000,500},K5:M5)) -> 0 | R5: =IF(COUNT(O5:Q5)=0,0,SUMPRODUCT({5000,1000,500},O5:Q5)) -> 0 | V5: 1 | X5: 49 | Z5: 78 | AB5: 2 | AC5: 1 | AD5: =IF(COUNT(S5:AC5)=0,0,SUMPRODUCT({5000,1000,500,100,75,50,20,10,5,2,1}, S5:AC5)) -> 3335 | AE5: 210846 | AF5: =IF(AND(COUNT(C5:E5)=0,COUNT(G5:I5)=0,COUNT(K5:M5)=0,COUNT(O5:Q5)=0,COUNT(S5:AC5)=0,AE5=""),"",(IF(COUNT(C5:E5)=0,0,SUMPRODUCT({5000,1000,500},C5:E5))+IF(COUNT(G5:I5)=0,0,SUMPRODUCT({5000,1000,500},G5:I5))+IF(COUNT(K5:M5)=0,0,SUMPRODUCT({5000,1000,500},K5:M5))+IF(COUNT(O5:Q5)=0,0,SUMPRODUCT({5000,1000,500},O5:Q5))+AD5)-N(AE5)) -> -11 | AG5: =IF(AF5="","",IF(AF5>0,"Excess",IF(AF5<0,"Short","Balanced"))) -> Short | AI5: 454245 | AJ5: =59833+394411+1 -> 454245 | AK5: =IF(AND(AI5="",AJ5=""),"",N(AI5)-N(AJ5)) -> 0 | AL5: =IF(AK5="","",IF(AK5>0,"Bank Short",IF(AK5<0,"Bank Excess","Matched"))) -> Matched
A6: 67249 | B6: =IF(A6="","",VLOOKUP(A6,'Employee Database'!A:B,2,FALSE)) -> Hanan Javaid | C6: 2 | D6: 32 | E6: 5 | F6: =IF(COUNT(C6:E6)=0,0,SUMPRODUCT({5000,1000,500},C6:E6)) -> 44500 | J6: =IF(COUNT(G6:I6)=0,0,SUMPRODUCT({5000,1000,500},G6:I6)) -> 0 | N6: =IF(COUNT(K6:M6)=0,0,SUMPRODUCT({5000,1000,500},K6:M6)) -> 0 | R6: =IF(COUNT(O6:Q6)=0,0,SUMPRODUCT({5000,1000,500},O6:Q6)) -> 0 | V6: 6 | X6: 111 | Z6: 97 | AD6: =IF(COUNT(S6:AC6)=0,0,SUMPRODUCT({5000,1000,500,100,75,50,20,10,5,2,1}, S6:AC6)) -> 7120 | AE6: 51641 | AF6: =IF(AND(COUNT(C6:E6)=0,COUNT(G6:I6)=0,COUNT(K6:M6)=0,COUNT(O6:Q6)=0,COUNT(S6:AC6)=0,AE6=""),"",(IF(COUNT(C6:E6)=0,0,SUMPRODUCT({5000,1000,500},C6:E6))+IF(COUNT(G6:I6)=0,0,SUMPRODUCT({5000,1000,500},G6:I6))+IF(COUNT(K6:M6)=0,0,SUMPRODUCT({5000,1000,500},K6:M6))+IF(COUNT(O6:Q6)=0,0,SUMPRODUCT({5000,1000,500},O6:Q6))+AD6)-N(AE6)) -> -21 | AG6: =IF(AF6="","",IF(AF6>0,"Excess",IF(AF6<0,"Short","Balanced"))) -> Short | AI6: 24756 | AJ6: =13330+11426 -> 24756 | AK6: =IF(AND(AI6="",AJ6=""),"",N(AI6)-N(AJ6)) -> 0 | AL6: =IF(AK6="","",IF(AK6>0,"POS Excess",IF(AK6<0,"Bank Short","Matched"))) -> Matched
A7: 72873 | B7: =IF(A7="","",VLOOKUP(A7,'Employee Database'!A:B,2,FALSE)) -> M Shajee | C7: 62 | D7: 191 | E7: 10 | F7: =IF(COUNT(C7:E7)=0,0,SUMPRODUCT({5000,1000,500},C7:E7)) -> 506000 | J7: =IF(COUNT(G7:I7)=0,0,SUMPRODUCT({5000,1000,500},G7:I7)) -> 0 | N7: =IF(COUNT(K7:M7)=0,0,SUMPRODUCT({5000,1000,500},K7:M7)) -> 0 | R7: =IF(COUNT(O7:Q7)=0,0,SUMPRODUCT({5000,1000,500},O7:Q7)) -> 0 | X7: 7 | Z7: 22 | AD7: =IF(COUNT(S7:AC7)=0,0,SUMPRODUCT({5000,1000,500,100,75,50,20,10,5,2,1}, S7:AC7)) -> 570 | AE7: 505522 | AF7: =IF(AND(COUNT(C7:E7)=0,COUNT(G7:I7)=0,COUNT(K7:M7)=0,COUNT(O7:Q7)=0,COUNT(S7:AC7)=0,AE7=""),"",(IF(COUNT(C7:E7)=0,0,SUMPRODUCT({5000,1000,500},C7:E7))+IF(COUNT(G7:I7)=0,0,SUMPRODUCT({5000,1000,500},G7:I7))+IF(COUNT(K7:M7)=0,0,SUMPRODUCT({5000,1000,500},K7:M7))+IF(COUNT(O7:Q7)=0,0,SUMPRODUCT({5000,1000,500},O7:Q7))+AD7)-N(AE7)) -> 1048 | AG7: =IF(AF7="","",IF(AF7>0,"Excess",IF(AF7<0,"Short","Balanced"))) -> Excess | AI7: 803582 | AJ7: =472623+330959 -> 803582 | AK7: =IF(AND(AI7="",AJ7=""),"",N(AI7)-N(AJ7)) -> 0 | AL7: =IF(AK7="","",IF(AK7>0,"POS Excess",IF(AK7<0,"Bank Short","Matched"))) -> Matched
A8: 65299 | B8: =IF(A8="","",VLOOKUP(A8,'Employee Database'!A:B,2,FALSE)) -> M Faisal | C8: 22 | D8: 81 | F8: =IF(COUNT(C8:E8)=0,0,SUMPRODUCT({5000,1000,500},C8:E8)) -> 191000 | J8: =IF(COUNT(G8:I8)=0,0,SUMPRODUCT({5000,1000,500},G8:I8)) -> 0 | N8: =IF(COUNT(K8:M8)=0,0,SUMPRODUCT({5000,1000,500},K8:M8)) -> 0 | R8: =IF(COUNT(O8:Q8)=0,0,SUMPRODUCT({5000,1000,500},O8:Q8)) -> 0 | X8: 47 | Z8: 52 | AD8: =IF(COUNT(S8:AC8)=0,0,SUMPRODUCT({5000,1000,500,100,75,50,20,10,5,2,1}, S8:AC8)) -> 2870 | AE8: 193888 | AF8: =IF(AND(COUNT(C8:E8)=0,COUNT(G8:I8)=0,COUNT(K8:M8)=0,COUNT(O8:Q8)=0,COUNT(S8:AC8)=0,AE8=""),"",(IF(COUNT(C8:E8)=0,0,SUMPRODUCT({5000,1000,500},C8:E8))+IF(COUNT(G8:I8)=0,0,SUMPRODUCT({5000,1000,500},G8:I8))+IF(COUNT(K8:M8)=0,0,SUMPRODUCT({5000,1000,500},K8:M8))+IF(COUNT(O8:Q8)=0,0,SUMPRODUCT({5000,1000,500},O8:Q8))+AD8)-N(AE8)) -> -18 | AG8: =IF(AF8="","",IF(AF8>0,"Excess",IF(AF8<0,"Short","Balanced"))) -> Short | AI8: 756891 | AJ8: =407718+349173 -> 756891 | AK8: =IF(AND(AI8="",AJ8=""),"",N(AI8)-N(AJ8)) -> 0 | AL8: =IF(AK8="","",IF(AK8>0,"POS Excess",IF(AK8<0,"Bank Short","Matched"))) -> Matched
A9: 73196 | B9: =IF(A9="","",VLOOKUP(A9,'Employee Database'!A:B,2,FALSE)) -> Asma | C9: 47 | D9: 81 | E9: 18 | F9: =IF(COUNT(C9:E9)=0,0,SUMPRODUCT({5000,1000,500},C9:E9)) -> 325000 | J9: =IF(COUNT(G9:I9)=0,0,SUMPRODUCT({5000,1000,500},G9:I9)) -> 0 | N9: =IF(COUNT(K9:M9)=0,0,SUMPRODUCT({5000,1000,500},K9:M9)) -> 0 | R9: =IF(COUNT(O9:Q9)=0,0,SUMPRODUCT({5000,1000,500},O9:Q9)) -> 0 | X9: 3 | Z9: 16 | AD9: =IF(COUNT(S9:AC9)=0,0,SUMPRODUCT({5000,1000,500,100,75,50,20,10,5,2,1}, S9:AC9)) -> 310 | AE9: 325367 | AF9: =IF(AND(COUNT(C9:E9)=0,COUNT(G9:I9)=0,COUNT(K9:M9)=0,COUNT(O9:Q9)=0,COUNT(S9:AC9)=0,AE9=""),"",(IF(COUNT(C9:E9)=0,0,SUMPRODUCT({5000,1000,500},C9:E9))+IF(COUNT(G9:I9)=0,0,SUMPRODUCT({5000,1000,500},G9:I9))+IF(COUNT(K9:M9)=0,0,SUMPRODUCT({5000,1000,500},K9:M9))+IF(COUNT(O9:Q9)=0,0,SUMPRODUCT({5000,1000,500},O9:Q9))+AD9)-N(AE9)) -> -57 | AG9: =IF(AF9="","",IF(AF9>0,"Excess",IF(AF9<0,"Short","Balanced"))) -> Short | AI9: =5091+797258 -> 802349 | AJ9: =5091+397161+400096+1 -> 802349 | AK9: =IF(AND(AI9="",AJ9=""),"",N(AI9)-N(AJ9)) -> 0 | AL9: =IF(AK9="","",IF(AK9>0,"POS Excess",IF(AK9<0,"Bank Short","Matched"))) -> Matched
A10: 57653 | B10: =IF(A10="","",VLOOKUP(A10,'Employee Database'!A:B,2,FALSE)) -> Amanat ali | C10: 88 | D10: 178 | E10: 23 | F10: =IF(COUNT(C10:E10)=0,0,SUMPRODUCT({5000,1000,500},C10:E10)) -> 629500 | J10: =IF(COUNT(G10:I10)=0,0,SUMPRODUCT({5000,1000,500},G10:I10)) -> 0 | N10: =IF(COUNT(K10:M10)=0,0,SUMPRODUCT({5000,1000,500},K10:M10)) -> 0 | R10: =IF(COUNT(O10:Q10)=0,0,SUMPRODUCT({5000,1000,500},O10:Q10)) -> 0 | V10: 1 | X10: 51 | Z10: 15 | AD10: =IF(COUNT(S10:AC10)=0,0,SUMPRODUCT({5000,1000,500,100,75,50,20,10,5,2,1}, S10:AC10)) -> 2800 | AE10: 632245 | AF10: =IF(AND(COUNT(C10:E10)=0,COUNT(G10:I10)=0,COUNT(K10:M10)=0,COUNT(O10:Q10)=0,COUNT(S10:AC10)=0,AE10=""),"",(IF(COUNT(C10:E10)=0,0,SUMPRODUCT({5000,1000,500},C10:E10))+IF(COUNT(G10:I10)=0,0,SUMPRODUCT({5000,1000,500},G10:I10))+IF(COUNT(K10:M10)=0,0,SUMPRODUCT({5000,1000,500},K10:M10))+IF(COUNT(O10:Q10)=0,0,SUMPRODUCT({5000,1000,500},O10:Q10))+AD10)-N(AE10)) -> 55 | AG10: =IF(AF10="","",IF(AF10>0,"Excess",IF(AF10<0,"Short","Balanced"))) -> Excess | AI10: 922878 | AJ10: 922878 | AK10: =IF(AND(AI10="",AJ10=""),"",N(AI10)-N(AJ10)) -> 0 | AL10: =IF(AK10="","",IF(AK10>0,"POS Excess",IF(AK10<0,"Bank Short","Matched"))) -> Matched
A11: 56189 | B11: =IF(A11="","",VLOOKUP(A11,'Employee Database'!A:B,2,FALSE)) -> Iffat Sultan | C11: 17 | D11: 78 | F11: =IF(COUNT(C11:E11)=0,0,SUMPRODUCT({5000,1000,500},C11:E11)) -> 163000 | J11: =IF(COUNT(G11:I11)=0,0,SUMPRODUCT({5000,1000,500},G11:I11)) -> 0 | N11: =IF(COUNT(K11:M11)=0,0,SUMPRODUCT({5000,1000,500},K11:M11)) -> 0 | R11: =IF(COUNT(O11:Q11)=0,0,SUMPRODUCT({5000,1000,500},O11:Q11)) -> 0 | X11: 7 | Z11: 10 | AD11: =IF(COUNT(S11:AC11)=0,0,SUMPRODUCT({5000,1000,500,100,75,50,20,10,5,2,1}, S11:AC11)) -> 450 | AE11: 163314 | AF11: =IF(AND(COUNT(C11:E11)=0,COUNT(G11:I11)=0,COUNT(K11:M11)=0,COUNT(O11:Q11)=0,COUNT(S11:AC11)=0,AE11=""),"",(IF(COUNT(C11:E11)=0,0,SUMPRODUCT({5000,1000,500},C11:E11))+IF(COUNT(G11:I11)=0,0,SUMPRODUCT({5000,1000,500},G11:I11))+IF(COUNT(K11:M11)=0,0,SUMPRODUCT({5000,1000,500},K11:M11))+IF(COUNT(O11:Q11)=0,0,SUMPRODUCT({5000,1000,500},O11:Q11))+AD11)-N(AE11)) -> 136 | AG11: =IF(AF11="","",IF(AF11>0,"Excess",IF(AF11<0,"Short","Balanced"))) -> Excess | AI11: =985856+5698.41 -> 991554.41 | AJ11: =333562+5698+652294.41 -> 991554.41 | AK11: =IF(AND(AI11="",AJ11=""),"",N(AI11)-N(AJ11)) -> 0 | AL11: =IF(AK11="","",IF(AK11>0,"POS Excess",IF(AK11<0,"Bank Short","Matched"))) -> Matched
A12: 50266 | B12: =IF(A12="","",VLOOKUP(A12,'Employee Database'!A:B,2,FALSE)) -> Riaz | C12: 21 | D12: 20 | E12: 2 | F12: =IF(COUNT(C12:E12)=0,0,SUMPRODUCT({5000,1000,500},C12:E12)) -> 126000 | J12: =IF(COUNT(G12:I12)=0,0,SUMPRODUCT({5000,1000,500},G12:I12)) -> 0 | N12: =IF(COUNT(K12:M12)=0,0,SUMPRODUCT({5000,1000,500},K12:M12)) -> 0 | R12: =IF(COUNT(O12:Q12)=0,0,SUMPRODUCT({5000,1000,500},O12:Q12)) -> 0 | X12: 75 | Z12: 65 | AD12: =IF(COUNT(S12:AC12)=0,0,SUMPRODUCT({5000,1000,500,100,75,50,20,10,5,2,1}, S12:AC12)) -> 4400 | AE12: 130298 | AF12: =IF(AND(COUNT(C12:E12)=0,COUNT(G12:I12)=0,COUNT(K12:M12)=0,COUNT(O12:Q12)=0,COUNT(S12:AC12)=0,AE12=""),"",(IF(COUNT(C12:E12)=0,0,SUMPRODUCT({5000,1000,500},C12:E12))+IF(COUNT(G12:I12)=0,0,SUMPRODUCT({5000,1000,500},G12:I12))+IF(COUNT(K12:M12)=0,0,SUMPRODUCT({5000,1000,500},K12:M12))+IF(COUNT(O12:Q12)=0,0,SUMPRODUCT({5000,1000,500},O12:Q12))+AD12)-N(AE12)) -> 102 | AG12: =IF(AF12="","",IF(AF12>0,"Excess",IF(AF12<0,"Short","Balanced"))) -> Excess | AI12: 431781 | AJ12: =139821+291960 -> 431781 | AK12: =IF(AND(AI12="",AJ12=""),"",N(AI12)-N(AJ12)) -> 0 | AL12: =IF(AK12="","",IF(AK12>0,"POS Excess",IF(AK12<0,"Bank Short","Matched"))) -> Matched
A13: 63854 | B13: =IF(A13="","",VLOOKUP(A13,'Employee Database'!A:B,2,FALSE)) -> Maham | C13: 26 | D13: 163 | E13: 30 | F13: =IF(COUNT(C13:E13)=0,0,SUMPRODUCT({5000,1000,500},C13:E13)) -> 308000 | J13: =IF(COUNT(G13:I13)=0,0,SUMPRODUCT({5000,1000,500},G13:I13)) -> 0 | N13: =IF(COUNT(K13:M13)=0,0,SUMPRODUCT({5000,1000,500},K13:M13)) -> 0 | R13: =IF(COUNT(O13:Q13)=0,0,SUMPRODUCT({5000,1000,500},O13:Q13)) -> 0 | V13: 1 | X13: 11 | Z13: 4 | AD13: =IF(COUNT(S13:AC13)=0,0,SUMPRODUCT({5000,1000,500,100,75,50,20,10,5,2,1}, S13:AC13)) -> 690 | AE13: 308595 | AF13: =IF(AND(COUNT(C13:E13)=0,COUNT(G13:I13)=0,COUNT(K13:M13)=0,COUNT(O13:Q13)=0,COUNT(S13:AC13)=0,AE13=""),"",(IF(COUNT(C13:E13)=0,0,SUMPRODUCT({5000,1000,500},C13:E13))+IF(COUNT(G13:I13)=0,0,SUMPRODUCT({5000,1000,500},G13:I13))+IF(COUNT(K13:M13)=0,0,SUMPRODUCT({5000,1000,500},K13:M13))+IF(COUNT(O13:Q13)=0,0,SUMPRODUCT({5000,1000,500},O13:Q13))+AD13)-N(AE13)) -> 95 | AG13: =IF(AF13="","",IF(AF13>0,"Excess",IF(AF13<0,"Short","Balanced"))) -> Excess | AI13: =315+304128 -> 304443 | AJ13: =161473+315+142655 -> 304443 | AK13: =IF(AND(AI13="",AJ13=""),"",N(AI13)-N(AJ13)) -> 0 | AL13: =IF(AK13="","",IF(AK13>0,"POS Excess",IF(AK13<0,"Bank Short","Matched"))) -> Matched
A14: 55417 | B14: =IF(A14="","",VLOOKUP(A14,'Employee Database'!A:B,2,FALSE)) -> M Imran | F14: =IF(COUNT(C14:E14)=0,0,SUMPRODUCT({5000,1000,500},C14:E14)) -> 0 | G14: 11 | H14: 10 | I14: 4 | J14: =IF(COUNT(G14:I14)=0,0,SUMPRODUCT({5000,1000,500},G14:I14)) -> 67000 | N14: =IF(COUNT(K14:M14)=0,0,SUMPRODUCT({5000,1000,500},K14:M14)) -> 0 | R14: =IF(COUNT(O14:Q14)=0,0,SUMPRODUCT({5000,1000,500},O14:Q14)) -> 0 | V14: 1 | X14: 82 | Z14: 93 | AD14: =IF(COUNT(S14:AC14)=0,0,SUMPRODUCT({5000,1000,500,100,75,50,20,10,5,2,1}, S14:AC14)) -> 5130 | AE14: 72124 | AF14: =IF(AND(COUNT(C14:E14)=0,COUNT(G14:I14)=0,COUNT(K14:M14)=0,COUNT(O14:Q14)=0,COUNT(S14:AC14)=0,AE14=""),"",(IF(COUNT(C14:E14)=0,0,SUMPRODUCT({5000,1000,500},C14:E14))+IF(COUNT(G14:I14)=0,0,SUMPRODUCT({5000,1000,500},G14:I14))+IF(COUNT(K14:M14)=0,0,SUMPRODUCT({5000,1000,500},K14:M14))+IF(COUNT(O14:Q14)=0,0,SUMPRODUCT({5000,1000,500},O14:Q14))+AD14)-N(AE14)) -> 6 | AG14: =IF(AF14="","",IF(AF14>0,"Excess",IF(AF14<0,"Short","Balanced"))) -> Excess | AI14: 412634.78 | AJ14: 412634.78 | AK14: =IF(AND(AI14="",AJ14=""),"",N(AI14)-N(AJ14)) -> 0 | AL14: =IF(AK14="","",IF(AK14>0,"POS Excess",IF(AK14<0,"Bank Short","Matched"))) -> Matched
A15: 50134 | B15: =IF(A15="","",VLOOKUP(A15,'Employee Database'!A:B,2,FALSE)) -> Asif Abbas | F15: =IF(COUNT(C15:E15)=0,0,SUMPRODUCT({5000,1000,500},C15:E15)) -> 0 | G15: 7 | H15: 16 | I15: 10 | J15: =IF(COUNT(G15:I15)=0,0,SUMPRODUCT({5000,1000,500},G15:I15)) -> 56000 | N15: =IF(COUNT(K15:M15)=0,0,SUMPRODUCT({5000,1000,500},K15:M15)) -> 0 | R15: =IF(COUNT(O15:Q15)=0,0,SUMPRODUCT({5000,1000,500},O15:Q15)) -> 0 | X15: 6 | Z15: 74 | AD15: =IF(COUNT(S15:AC15)=0,0,SUMPRODUCT({5000,1000,500,100,75,50,20,10,5,2,1}, S15:AC15)) -> 1040 | AE15: 57019 | AF15: =IF(AND(COUNT(C15:E15)=0,COUNT(G15:I15)=0,COUNT(K15:M15)=0,COUNT(O15:Q15)=0,COUNT(S15:AC15)=0,AE15=""),"",(IF(COUNT(C15:E15)=0,0,SUMPRODUCT({5000,1000,500},C15:E15))+IF(COUNT(G15:I15)=0,0,SUMPRODUCT({5000,1000,500},G15:I15))+IF(COUNT(K15:M15)=0,0,SUMPRODUCT({5000,1000,500},K15:M15))+IF(COUNT(O15:Q15)=0,0,SUMPRODUCT({5000,1000,500},O15:Q15))+AD15)-N(AE15)) -> 21 | AG15: =IF(AF15="","",IF(AF15>0,"Excess",IF(AF15<0,"Short","Balanced"))) -> Excess | AI15: =63344.6+96275.1 -> 159619.7 | AJ15: =63344.6+96275.1 -> 159619.7 | AK15: =IF(AND(AI15="",AJ15=""),"",N(AI15)-N(AJ15)) -> 0 | AL15: =IF(AK15="","",IF(AK15>0,"POS Excess",IF(AK15<0,"Bank Short","Matched"))) -> Matched
A16: 71788 | B16: =IF(A16="","",VLOOKUP(A16,'Employee Database'!A:B,2,FALSE)) -> Saaim | F16: =IF(COUNT(C16:E16)=0,0,SUMPRODUCT({5000,1000,500},C16:E16)) -> 0 | G16: 48 | H16: 53 | I16: 2 | J16: =IF(COUNT(G16:I16)=0,0,SUMPRODUCT({5000,1000,500},G16:I16)) -> 294000 | N16: =IF(COUNT(K16:M16)=0,0,SUMPRODUCT({5000,1000,500},K16:M16)) -> 0 | R16: =IF(COUNT(O16:Q16)=0,0,SUMPRODUCT({5000,1000,500},O16:Q16)) -> 0 | X16: 25 | Y16: 1 | Z16: 66 | AD16: =IF(COUNT(S16:AC16)=0,0,SUMPRODUCT({5000,1000,500,100,75,50,20,10,5,2,1}, S16:AC16)) -> 1930 | AE16: 296104 | AF16: =IF(AND(COUNT(C16:E16)=0,COUNT(G16:I16)=0,COUNT(K16:M16)=0,COUNT(O16:Q16)=0,COUNT(S16:AC16)=0,AE16=""),"",(IF(COUNT(C16:E16)=0,0,SUMPRODUCT({5000,1000,500},C16:E16))+IF(COUNT(G16:I16)=0,0,SUMPRODUCT({5000,1000,500},G16:I16))+IF(COUNT(K16:M16)=0,0,SUMPRODUCT({5000,1000,500},K16:M16))+IF(COUNT(O16:Q16)=0,0,SUMPRODUCT({5000,1000,500},O16:Q16))+AD16)-N(AE16)) -> -174 | AG16: =IF(AF16="","",IF(AF16>0,"Excess",IF(AF16<0,"Short","Balanced"))) -> Short | AI16: 982781.9 | AJ16: =227614.09+147143.84+608023.97 -> 982781.9 | AK16: =IF(AND(AI16="",AJ16=""),"",N(AI16)-N(AJ16)) -> 1.1641532e-10 | AL16: =IF(AK16="","",IF(AK16>0,"POS Excess",IF(AK16<0,"Bank Short","Matched"))) -> POS Excess
A17: 67799 | B17: =IF(A17="","",VLOOKUP(A17,'Employee Database'!A:B,2,FALSE)) -> Hassan Raza | F17: =IF(COUNT(C17:E17)=0,0,SUMPRODUCT({5000,1000,500},C17:E17)) -> 0 | G17: 96 | H17: 111 | I17: 12 | J17: =IF(COUNT(G17:I17)=0,0,SUMPRODUCT({5000,1000,500},G17:I17)) -> 597000 | N17: =IF(COUNT(K17:M17)=0,0,SUMPRODUCT({5000,1000,500},K17:M17)) -> 0 | R17: =IF(COUNT(O17:Q17)=0,0,SUMPRODUCT({5000,1000,500},O17:Q17)) -> 0 | V17: 3 | X17: 89 | Y17: 2 | Z17: 70 | AD17: =IF(COUNT(S17:AC17)=0,0,SUMPRODUCT({5000,1000,500,100,75,50,20,10,5,2,1}, S17:AC17)) -> 5490 | AE17: 602684 | AF17: =IF(AND(COUNT(C17:E17)=0,COUNT(G17:I17)=0,COUNT(K17:M17)=0,COUNT(O17:Q17)=0,COUNT(S17:AC17)=0,AE17=""),"",(IF(COUNT(C17:E17)=0,0,SUMPRODUCT({5000,1000,500},C17:E17))+IF(COUNT(G17:I17)=0,0,SUMPRODUCT({5000,1000,500},G17:I17))+IF(COUNT(K17:M17)=0,0,SUMPRODUCT({5000,1000,500},K17:M17))+IF(COUNT(O17:Q17)=0,0,SUMPRODUCT({5000,1000,500},O17:Q17))+AD17)-N(AE17)) -> -194 | AG17: =IF(AF17="","",IF(AF17>0,"Excess",IF(AF17<0,"Short","Balanced"))) -> Short | AI17: 356402.04 | AJ17: =44760.81+291864.5+19776 -> 356401.31 | AK17: =IF(AND(AI17="",AJ17=""),"",N(AI17)-N(AJ17)) -> 0.73 | AL17: =IF(AK17="","",IF(AK17>0,"POS Excess",IF(AK17<0,"Bank Short","Matched"))) -> POS Excess
A18: 63599 | B18: =IF(A18="","",VLOOKUP(A18,'Employee Database'!A:B,2,FALSE)) -> Hafsa | F18: =IF(COUNT(C18:E18)=0,0,SUMPRODUCT({5000,1000,500},C18:E18)) -> 0 | G18: 24 | H18: 30 | I18: 1 | J18: =IF(COUNT(G18:I18)=0,0,SUMPRODUCT({5000,1000,500},G18:I18)) -> 150500 | N18: =IF(COUNT(K18:M18)=0,0,SUMPRODUCT({5000,1000,500},K18:M18)) -> 0 | R18: =IF(COUNT(O18:Q18)=0,0,SUMPRODUCT({5000,1000,500},O18:Q18)) -> 0 | V18: 1 | X18: 48 | Z18: 78 | AD18: =IF(COUNT(S18:AC18)=0,0,SUMPRODUCT({5000,1000,500,100,75,50,20,10,5,2,1}, S18:AC18)) -> 3280 | AE18: 153739 | AF18: =IF(AND(COUNT(C18:E18)=0,COUNT(G18:I18)=0,COUNT(K18:M18)=0,COUNT(O18:Q18)=0,COUNT(S18:AC18)=0,AE18=""),"",(IF(COUNT(C18:E18)=0,0,SUMPRODUCT({5000,1000,500},C18:E18))+IF(COUNT(G18:I18)=0,0,SUMPRODUCT({5000,1000,500},G18:I18))+IF(COUNT(K18:M18)=0,0,SUMPRODUCT({5000,1000,500},K18:M18))+IF(COUNT(O18:Q18)=0,0,SUMPRODUCT({5000,1000,500},O18:Q18))+AD18)-N(AE18)) -> 41 | AG18: =IF(AF18="","",IF(AF18>0,"Excess",IF(AF18<0,"Short","Balanced"))) -> Excess | AI18: 576068.36 | AJ18: 576068.36 | AK18: =IF(AND(AI18="",AJ18=""),"",N(AI18)-N(AJ18)) -> 0 | AL18: =IF(AK18="","",IF(AK18>0,"POS Excess",IF(AK18<0,"Bank Short","Matched"))) -> Matched
A19: 61648 | B19: =IF(A19="","",VLOOKUP(A19,'Employee Database'!A:B,2,FALSE)) -> Rizwan | F19: =IF(COUNT(C19:E19)=0,0,SUMPRODUCT({5000,1000,500},C19:E19)) -> 0 | G19: 17 | H19: 27 | I19: 10 | J19: =IF(COUNT(G19:I19)=0,0,SUMPRODUCT({5000,1000,500},G19:I19)) -> 117000 | N19: =IF(COUNT(K19:M19)=0,0,SUMPRODUCT({5000,1000,500},K19:M19)) -> 0 | R19: =IF(COUNT(O19:Q19)=0,0,SUMPRODUCT({5000,1000,500},O19:Q19)) -> 0 | V19: 1 | X19: 68 | Y19: 2 | Z19: 94 | AD19: =IF(COUNT(S19:AC19)=0,0,SUMPRODUCT({5000,1000,500,100,75,50,20,10,5,2,1}, S19:AC19)) -> 4480 | AE19: 121454 | AF19: =IF(AND(COUNT(C19:E19)=0,COUNT(G19:I19)=0,COUNT(K19:M19)=0,COUNT(O19:Q19)=0,COUNT(S19:AC19)=0,AE19=""),"",(IF(COUNT(C19:E19)=0,0,SUMPRODUCT({5000,1000,500},C19:E19))+IF(COUNT(G19:I19)=0,0,SUMPRODUCT({5000,1000,500},G19:I19))+IF(COUNT(K19:M19)=0,0,SUMPRODUCT({5000,1000,500},K19:M19))+IF(COUNT(O19:Q19)=0,0,SUMPRODUCT({5000,1000,500},O19:Q19))+AD19)-N(AE19)) -> 26 | AG19: =IF(AF19="","",IF(AF19>0,"Excess",IF(AF19<0,"Short","Balanced"))) -> Excess | AI19: =44473.91+134259.28+204829.35 -> 383562.54 | AJ19: =2906+131353.28+7416.82+37057.09+160687.44+44141.91 -> 383562.54 | AK19: =IF(AND(AI19="",AJ19=""),"",N(AI19)-N(AJ19)) -> 0 | AL19: =IF(AK19="","",IF(AK19>0,"POS Excess",IF(AK19<0,"Bank Short","Matched"))) -> Matched
A20: 69732 | B20: =IF(A20="","",VLOOKUP(A20,'Employee Database'!A:B,2,FALSE)) -> Abdul Hafeez | F20: =IF(COUNT(C20:E20)=0,0,SUMPRODUCT({5000,1000,500},C20:E20)) -> 0 | G20: 27 | H20: 159 | I20: 16 | J20: =IF(COUNT(G20:I20)=0,0,SUMPRODUCT({5000,1000,500},G20:I20)) -> 302000 | N20: =IF(COUNT(K20:M20)=0,0,SUMPRODUCT({5000,1000,500},K20:M20)) -> 0 | R20: =IF(COUNT(O20:Q20)=0,0,SUMPRODUCT({5000,1000,500},O20:Q20)) -> 0 | V20: 9 | X20: 12 | Z20: 37 | AD20: =IF(COUNT(S20:AC20)=0,0,SUMPRODUCT({5000,1000,500,100,75,50,20,10,5,2,1}, S20:AC20)) -> 1870 | AE20: 303851 | AF20: =IF(AND(COUNT(C20:E20)=0,COUNT(G20:I20)=0,COUNT(K20:M20)=0,COUNT(O20:Q20)=0,COUNT(S20:AC20)=0,AE20=""),"",(IF(COUNT(C20:E20)=0,0,SUMPRODUCT({5000,1000,500},C20:E20))+IF(COUNT(G20:I20)=0,0,SUMPRODUCT({5000,1000,500},G20:I20))+IF(COUNT(K20:M20)=0,0,SUMPRODUCT({5000,1000,500},K20:M20))+IF(COUNT(O20:Q20)=0,0,SUMPRODUCT({5000,1000,500},O20:Q20))+AD20)-N(AE20)) -> 19 | AG20: =IF(AF20="","",IF(AF20>0,"Excess",IF(AF20<0,"Short","Balanced"))) -> Excess | AI20: 548945.02 | AJ20: =5899.94+543045.08 -> 548945.02 | AK20: =IF(AND(AI20="",AJ20=""),"",N(AI20)-N(AJ20)) -> 1.1641532e-10 | AL20: =IF(AK20="","",IF(AK20>0,"POS Excess",IF(AK20<0,"Bank Short","Matched"))) -> POS Excess
A21: 68475 | B21: =IF(A21="","",VLOOKUP(A21,'Employee Database'!A:B,2,FALSE)) -> M Azeem | F21: =IF(COUNT(C21:E21)=0,0,SUMPRODUCT({5000,1000,500},C21:E21)) -> 0 | G21: 30 | H21: 84 | I21: 16 | J21: =IF(COUNT(G21:I21)=0,0,SUMPRODUCT({5000,1000,500},G21:I21)) -> 242000 | N21: =IF(COUNT(K21:M21)=0,0,SUMPRODUCT({5000,1000,500},K21:M21)) -> 0 | R21: =IF(COUNT(O21:Q21)=0,0,SUMPRODUCT({5000,1000,500},O21:Q21)) -> 0 | V21: 6 | X21: 6 | Z21: 57 | AD21: =IF(COUNT(S21:AC21)=0,0,SUMPRODUCT({5000,1000,500,100,75,50,20,10,5,2,1}, S21:AC21)) -> 1470 | AE21: 243454 | AF21: =IF(AND(COUNT(C21:E21)=0,COUNT(G21:I21)=0,COUNT(K21:M21)=0,COUNT(O21:Q21)=0,COUNT(S21:AC21)=0,AE21=""),"",(IF(COUNT(C21:E21)=0,0,SUMPRODUCT({5000,1000,500},C21:E21))+IF(COUNT(G21:I21)=0,0,SUMPRODUCT({5000,1000,500},G21:I21))+IF(COUNT(K21:M21)=0,0,SUMPRODUCT({5000,1000,500},K21:M21))+IF(COUNT(O21:Q21)=0,0,SUMPRODUCT({5000,1000,500},O21:Q21))+AD21)-N(AE21)) -> 16 | AG21: =IF(AF21="","",IF(AF21>0,"Excess",IF(AF21<0,"Short","Balanced"))) -> Excess | AI21: 807508.87 | AJ21: =480338.26+327170.61 -> 807508.87 | AK21: =IF(AND(AI21="",AJ21=""),"",N(AI21)-N(AJ21)) -> 0 | AL21: =IF(AK21="","",IF(AK21>0,"POS Excess",IF(AK21<0,"Bank Short","Matched"))) -> Matched
A22: 69728 | B22: =IF(A22="","",VLOOKUP(A22,'Employee Database'!A:B,2,FALSE)) -> Hafiz Hafeez Ur Rehman | F22: =IF(COUNT(C22:E22)=0,0,SUMPRODUCT({5000,1000,500},C22:E22)) -> 0 | G22: 44 | H22: 76 | I22: 104 | J22: =IF(COUNT(G22:I22)=0,0,SUMPRODUCT({5000,1000,500},G22:I22)) -> 348000 | N22: =IF(COUNT(K22:M22)=0,0,SUMPRODUCT({5000,1000,500},K22:M22)) -> 0 | R22: =IF(COUNT(O22:Q22)=0,0,SUMPRODUCT({5000,1000,500},O22:Q22)) -> 0 | V22: 18 | X22: 37 | Y22: 1 | Z22: 60 | AD22: =IF(COUNT(S22:AC22)=0,0,SUMPRODUCT({5000,1000,500,100,75,50,20,10,5,2,1}, S22:AC22)) -> 4270 | AE22: 352271 | AF22: =IF(AND(COUNT(C22:E22)=0,COUNT(G22:I22)=0,COUNT(K22:M22)=0,COUNT(O22:Q22)=0,COUNT(S22:AC22)=0,AE22=""),"",(IF(COUNT(C22:E22)=0,0,SUMPRODUCT({5000,1000,500},C22:E22))+IF(COUNT(G22:I22)=0,0,SUMPRODUCT({5000,1000,500},G22:I22))+IF(COUNT(K22:M22)=0,0,SUMPRODUCT({5000,1000,500},K22:M22))+IF(COUNT(O22:Q22)=0,0,SUMPRODUCT({5000,1000,500},O22:Q22))+AD22)-N(AE22)) -> -1 | AG22: =IF(AF22="","",IF(AF22>0,"Excess",IF(AF22<0,"Short","Balanced"))) -> Short | AI22: =288577.04+953245.41+26735 -> 1268557.4 | AJ22: =953245.41+288577.04+26735 -> 1268557.4 | AK22: =IF(AND(AI22="",AJ22=""),"",N(AI22)-N(AJ22)) -> 0 | AL22: =IF(AK22="","",IF(AK22>0,"POS Excess",IF(AK22<0,"Bank Short","Matched"))) -> Matched
A23: 75768 | B23: =IF(A23="","",VLOOKUP(A23,'Employee Database'!A:B,2,FALSE)) -> Zuhaib | F23: =IF(COUNT(C23:E23)=0,0,SUMPRODUCT({5000,1000,500},C23:E23)) -> 0 | G23: 60 | H23: 77 | I23: 44 | J23: =IF(COUNT(G23:I23)=0,0,SUMPRODUCT({5000,1000,500},G23:I23)) -> 399000 | N23: =IF(COUNT(K23:M23)=0,0,SUMPRODUCT({5000,1000,500},K23:M23)) -> 0 | R23: =IF(COUNT(O23:Q23)=0,0,SUMPRODUCT({5000,1000,500},O23:Q23)) -> 0 | V23: 3 | X23: 51 | Y23: 3 | Z23: 40 | AD23: =IF(COUNT(S23:AC23)=0,0,SUMPRODUCT({5000,1000,500,100,75,50,20,10,5,2,1}, S23:AC23)) -> 3310 | AE23: 402272 | AF23: =IF(AND(COUNT(C23:E23)=0,COUNT(G23:I23)=0,COUNT(K23:M23)=0,COUNT(O23:Q23)=0,COUNT(S23:AC23)=0,AE23=""),"",(IF(COUNT(C23:E23)=0,0,SUMPRODUCT({5000,1000,500},C23:E23))+IF(COUNT(G23:I23)=0,0,SUMPRODUCT({5000,1000,500},G23:I23))+IF(COUNT(K23:M23)=0,0,SUMPRODUCT({5000,1000,500},K23:M23))+IF(COUNT(O23:Q23)=0,0,SUMPRODUCT({5000,1000,500},O23:Q23))+AD23)-N(AE23)) -> 38 | AG23: =IF(AF23="","",IF(AF23>0,"Excess",IF(AF23<0,"Short","Balanced"))) -> Excess | AI23: =769332.53+229532.97 -> 998865.5 | AJ23: =94927.04+674405.49+229532.97 -> 998865.5 | AK23: =IF(AND(AI23="",AJ23=""),"",N(AI23)-N(AJ23)) -> 0 | AL23: =IF(AK23="","",IF(AK23>0,"POS Excess",IF(AK23<0,"Bank Short","Matched"))) -> Matched
A24: 73679 | B24: =IF(A24="","",VLOOKUP(A24,'Employee Database'!A:B,2,FALSE)) -> Imran Waqar | F24: =IF(COUNT(C24:E24)=0,0,SUMPRODUCT({5000,1000,500},C24:E24)) -> 0 | G24: 31 | H24: 165 | I24: 16 | J24: =IF(COUNT(G24:I24)=0,0,SUMPRODUCT({5000,1000,500},G24:I24)) -> 328000 | N24: =IF(COUNT(K24:M24)=0,0,SUMPRODUCT({5000,1000,500},K24:M24)) -> 0 | R24: =IF(COUNT(O24:Q24)=0,0,SUMPRODUCT({5000,1000,500},O24:Q24)) -> 0 | V24: 1 | X24: 126 | Z24: 53 | AD24: =IF(COUNT(S24:AC24)=0,0,SUMPRODUCT({5000,1000,500,100,75,50,20,10,5,2,1}, S24:AC24)) -> 6930 | AE24: 334897 | AF24: =IF(AND(COUNT(C24:E24)=0,COUNT(G24:I24)=0,COUNT(K24:M24)=0,COUNT(O24:Q24)=0,COUNT(S24:AC24)=0,AE24=""),"",(IF(COUNT(C24:E24)=0,0,SUMPRODUCT({5000,1000,500},C24:E24))+IF(COUNT(G24:I24)=0,0,SUMPRODUCT({5000,1000,500},G24:I24))+IF(COUNT(K24:M24)=0,0,SUMPRODUCT({5000,1000,500},K24:M24))+IF(COUNT(O24:Q24)=0,0,SUMPRODUCT({5000,1000,500},O24:Q24))+AD24)-N(AE24)) -> 33 | AG24: =IF(AF24="","",IF(AF24>0,"Excess",IF(AF24<0,"Short","Balanced"))) -> Excess | AI24: 1077870.3 | AJ24: =3172.55+1074697.76 -> 1077870.3 | AK24: =IF(AND(AI24="",AJ24=""),"",N(AI24)-N(AJ24)) -> 0 | AL24: =IF(AK24="","",IF(AK24>0,"POS Excess",IF(AK24<0,"Bank Short","Matched"))) -> Matched
A25: 79593 | B25: =IF(A25="","",VLOOKUP(A25,'Employee Database'!A:B,2,FALSE)) -> Amir | F25: =IF(COUNT(C25:E25)=0,0,SUMPRODUCT({5000,1000,500},C25:E25)) -> 0 | G25: 68 | H25: 75 | I25: 12 | J25: =IF(COUNT(G25:I25)=0,0,SUMPRODUCT({5000,1000,500},G25:I25)) -> 421000 | N25: =IF(COUNT(K25:M25)=0,0,SUMPRODUCT({5000,1000,500},K25:M25)) -> 0 | R25: =IF(COUNT(O25:Q25)=0,0,SUMPRODUCT({5000,1000,500},O25:Q25)) -> 0 | V25: 7 | X25: 3 | Z25: 43 | AD25: =IF(COUNT(S25:AC25)=0,0,SUMPRODUCT({5000,1000,500,100,75,50,20,10,5,2,1}, S25:AC25)) -> 1280 | AE25: 422255 | AF25: =IF(AND(COUNT(C25:E25)=0,COUNT(G25:I25)=0,COUNT(K25:M25)=0,COUNT(O25:Q25)=0,COUNT(S25:AC25)=0,AE25=""),"",(IF(COUNT(C25:E25)=0,0,SUMPRODUCT({5000,1000,500},C25:E25))+IF(COUNT(G25:I25)=0,0,SUMPRODUCT({5000,1000,500},G25:I25))+IF(COUNT(K25:M25)=0,0,SUMPRODUCT({5000,1000,500},K25:M25))+IF(COUNT(O25:Q25)=0,0,SUMPRODUCT({5000,1000,500},O25:Q25))+AD25)-N(AE25)) -> 25 | AG25: =IF(AF25="","",IF(AF25>0,"Excess",IF(AF25<0,"Short","Balanced"))) -> Excess | AI25: 901998.62 | AJ25: 901988.62 | AK25: =IF(AND(AI25="",AJ25=""),"",N(AI25)-N(AJ25)) -> 10 | AL25: =IF(AK25="","",IF(AK25>0,"POS Excess",IF(AK25<0,"Bank Short","Matched"))) -> POS Excess
A26: 53893 | B26: =IF(A26="","",VLOOKUP(A26,'Employee Database'!A:B,2,FALSE)) -> M Binyameen | F26: =IF(COUNT(C26:E26)=0,0,SUMPRODUCT({5000,1000,500},C26:E26)) -> 0 | G26: 62 | H26: 149 | I26: 78 | J26: =IF(COUNT(G26:I26)=0,0,SUMPRODUCT({5000,1000,500},G26:I26)) -> 498000 | N26: =IF(COUNT(K26:M26)=0,0,SUMPRODUCT({5000,1000,500},K26:M26)) -> 0 | R26: =IF(COUNT(O26:Q26)=0,0,SUMPRODUCT({5000,1000,500},O26:Q26)) -> 0 | V26: 42 | X26: 17 | Y26: 4 | Z26: 54 | AD26: =IF(COUNT(S26:AC26)=0,0,SUMPRODUCT({5000,1000,500,100,75,50,20,10,5,2,1}, S26:AC26)) -> 5670 | AE26: 503667 | AF26: =IF(AND(COUNT(C26:E26)=0,COUNT(G26:I26)=0,COUNT(K26:M26)=0,COUNT(O26:Q26)=0,COUNT(S26:AC26)=0,AE26=""),"",(IF(COUNT(C26:E26)=0,0,SUMPRODUCT({5000,1000,500},C26:E26))+IF(COUNT(G26:I26)=0,0,SUMPRODUCT({5000,1000,500},G26:I26))+IF(COUNT(K26:M26)=0,0,SUMPRODUCT({5000,1000,500},K26:M26))+IF(COUNT(O26:Q26)=0,0,SUMPRODUCT({5000,1000,500},O26:Q26))+AD26)-N(AE26)) -> 3 | AG26: =IF(AF26="","",IF(AF26>0,"Excess",IF(AF26<0,"Short","Balanced"))) -> Excess | AI26: =551584.31+302944.4 -> 854528.71 | AJ26: =114875.36+188069.04+551584.31 -> 854528.71 | AK26: =IF(AND(AI26="",AJ26=""),"",N(AI26)-N(AJ26)) -> 0 | AL26: =IF(AK26="","",IF(AK26>0,"POS Excess",IF(AK26<0,"Bank Short","Matched"))) -> Matched
A27: 78242 | B27: =IF(A27="","",VLOOKUP(A27,'Employee Database'!A:B,2,FALSE)) -> Hamad Mughal | F27: =IF(COUNT(C27:E27)=0,0,SUMPRODUCT({5000,1000,500},C27:E27)) -> 0 | G27: 66 | H27: 50 | I27: 1 | J27: =IF(COUNT(G27:I27)=0,0,SUMPRODUCT({5000,1000,500},G27:I27)) -> 380500 | N27: =IF(COUNT(K27:M27)=0,0,SUMPRODUCT({5000,1000,500},K27:M27)) -> 0 | R27: =IF(COUNT(O27:Q27)=0,0,SUMPRODUCT({5000,1000,500},O27:Q27)) -> 0 | Z27: 64 | AD27: =IF(COUNT(S27:AC27)=0,0,SUMPRODUCT({5000,1000,500,100,75,50,20,10,5,2,1}, S27:AC27)) -> 640 | AE27: 381133 | AF27: =IF(AND(COUNT(C27:E27)=0,COUNT(G27:I27)=0,COUNT(K27:M27)=0,COUNT(O27:Q27)=0,COUNT(S27:AC27)=0,AE27=""),"",(IF(COUNT(C27:E27)=0,0,SUMPRODUCT({5000,1000,500},C27:E27))+IF(COUNT(G27:I27)=0,0,SUMPRODUCT({5000,1000,500},G27:I27))+IF(COUNT(K27:M27)=0,0,SUMPRODUCT({5000,1000,500},K27:M27))+IF(COUNT(O27:Q27)=0,0,SUMPRODUCT({5000,1000,500},O27:Q27))+AD27)-N(AE27)) -> 7 | AG27: =IF(AF27="","",IF(AF27>0,"Excess",IF(AF27<0,"Short","Balanced"))) -> Excess | AI27: 685298.11 | AJ27: =602780.16+82517.95 -> 685298.11 | AK27: =IF(AND(AI27="",AJ27=""),"",N(AI27)-N(AJ27)) -> 0 | AL27: =IF(AK27="","",IF(AK27>0,"POS Excess",IF(AK27<0,"Bank Short","Matched"))) -> Matched
A28: 50524 | B28: =IF(A28="","",VLOOKUP(A28,'Employee Database'!A:B,2,FALSE)) -> Allah Rakha | F28: =IF(COUNT(C28:E28)=0,0,SUMPRODUCT({5000,1000,500},C28:E28)) -> 0 | G28: 17 | H28: 12 | I28: 5 | J28: =IF(COUNT(G28:I28)=0,0,SUMPRODUCT({5000,1000,500},G28:I28)) -> 99500 | N28: =IF(COUNT(K28:M28)=0,0,SUMPRODUCT({5000,1000,500},K28:M28)) -> 0 | R28: =IF(COUNT(O28:Q28)=0,0,SUMPRODUCT({5000,1000,500},O28:Q28)) -> 0 | V28: 1 | X28: 105 | Y28: 1 | Z28: 52 | AD28: =IF(COUNT(S28:AC28)=0,0,SUMPRODUCT({5000,1000,500,100,75,50,20,10,5,2,1}, S28:AC28)) -> 5890 | AE28: 105392 | AF28: =IF(AND(COUNT(C28:E28)=0,COUNT(G28:I28)=0,COUNT(K28:M28)=0,COUNT(O28:Q28)=0,COUNT(S28:AC28)=0,AE28=""),"",(IF(COUNT(C28:E28)=0,0,SUMPRODUCT({5000,1000,500},C28:E28))+IF(COUNT(G28:I28)=0,0,SUMPRODUCT({5000,1000,500},G28:I28))+IF(COUNT(K28:M28)=0,0,SUMPRODUCT({5000,1000,500},K28:M28))+IF(COUNT(O28:Q28)=0,0,SUMPRODUCT({5000,1000,500},O28:Q28))+AD28)-N(AE28)) -> -2 | AG28: =IF(AF28="","",IF(AF28>0,"Excess",IF(AF28<0,"Short","Balanced"))) -> Short | AI28: 520906 | AJ28: =183650.58+337255.42 -> 520906 | AK28: =IF(AND(AI28="",AJ28=""),"",N(AI28)-N(AJ28)) -> 0 | AL28: =IF(AK28="","",IF(AK28>0,"POS Excess",IF(AK28<0,"Bank Short","Matched"))) -> Matched
A29: 50313 | B29: =IF(A29="","",VLOOKUP(A29,'Employee Database'!A:B,2,FALSE)) -> Waseem Raza | F29: =IF(COUNT(C29:E29)=0,0,SUMPRODUCT({5000,1000,500},C29:E29)) -> 0 | G29: 0 | H29: 1 | I29: 2 | J29: =IF(COUNT(G29:I29)=0,0,SUMPRODUCT({5000,1000,500},G29:I29)) -> 2000 | N29: =IF(COUNT(K29:M29)=0,0,SUMPRODUCT({5000,1000,500},K29:M29)) -> 0 | R29: =IF(COUNT(O29:Q29)=0,0,SUMPRODUCT({5000,1000,500},O29:Q29)) -> 0 | V29: 2 | X29: 9 | Z29: 3 | AD29: =IF(COUNT(S29:AC29)=0,0,SUMPRODUCT({5000,1000,500,100,75,50,20,10,5,2,1}, S29:AC29)) -> 680 | AE29: 2681 | AF29: =IF(AND(COUNT(C29:E29)=0,COUNT(G29:I29)=0,COUNT(K29:M29)=0,COUNT(O29:Q29)=0,COUNT(S29:AC29)=0,AE29=""),"",(IF(COUNT(C29:E29)=0,0,SUMPRODUCT({5000,1000,500},C29:E29))+IF(COUNT(G29:I29)=0,0,SUMPRODUCT({5000,1000,500},G29:I29))+IF(COUNT(K29:M29)=0,0,SUMPRODUCT({5000,1000,500},K29:M29))+IF(COUNT(O29:Q29)=0,0,SUMPRODUCT({5000,1000,500},O29:Q29))+AD29)-N(AE29)) -> -1 | AG29: =IF(AF29="","",IF(AF29>0,"Excess",IF(AF29<0,"Short","Balanced"))) -> Short | AK29: =IF(AND(AI29="",AJ29=""),"",N(AI29)-N(AJ29)) | AL29: =IF(AK29="","",IF(AK29>0,"POS Excess",IF(AK29<0,"Bank Short","Matched")))
B30: =IF(A30="","",VLOOKUP(A30,'Employee Database'!A:B,2,FALSE)) | F30: =IF(COUNT(C30:E30)=0,0,SUMPRODUCT({5000,1000,500},C30:E30)) -> 0 | J30: =IF(COUNT(G30:I30)=0,0,SUMPRODUCT({5000,1000,500},G30:I30)) -> 0 | N30: =IF(COUNT(K30:M30)=0,0,SUMPRODUCT({5000,1000,500},K30:M30)) -> 0 | R30: =IF(COUNT(O30:Q30)=0,0,SUMPRODUCT({5000,1000,500},O30:Q30)) -> 0 | AD30: =IF(COUNT(S30:AC30)=0,0,SUMPRODUCT({5000,1000,500,100,75,50,20,10,5,2,1}, S30:AC30)) -> 0 | AF30: =IF(AND(COUNT(C30:E30)=0,COUNT(G30:I30)=0,COUNT(K30:M30)=0,COUNT(O30:Q30)=0,COUNT(S30:AC30)=0,AE30=""),"",(IF(COUNT(C30:E30)=0,0,SUMPRODUCT({5000,1000,500},C30:E30))+IF(COUNT(G30:I30)=0,0,SUMPRODUCT({5000,1000,500},G30:I30))+IF(COUNT(K30:M30)=0,0,SUMPRODUCT({5000,1000,500},K30:M30))+IF(COUNT(O30:Q30)=0,0,SUMPRODUCT({5000,1000,500},O30:Q30))+AD30)-N(AE30)) | AG30: =IF(AF30="","",IF(AF30>0,"Excess",IF(AF30<0,"Short","Balanced"))) | AK30: =IF(AND(AI30="",AJ30=""),"",N(AI30)-N(AJ30)) | AL30: =IF(AK30="","",IF(AK30>0,"POS Excess",IF(AK30<0,"Bank Short","Matched")))
B31: =IF(A31="","",VLOOKUP(A31,'Employee Database'!A:B,2,FALSE)) | F31: =IF(COUNT(C31:E31)=0,0,SUMPRODUCT({5000,1000,500},C31:E31)) -> 0 | J31: =IF(COUNT(G31:I31)=0,0,SUMPRODUCT({5000,1000,500},G31:I31)) -> 0 | N31: =IF(COUNT(K31:M31)=0,0,SUMPRODUCT({5000,1000,500},K31:M31)) -> 0 | R31: =IF(COUNT(O31:Q31)=0,0,SUMPRODUCT({5000,1000,500},O31:Q31)) -> 0 | AD31: =IF(COUNT(S31:AC31)=0,0,SUMPRODUCT({5000,1000,500,100,75,50,20,10,5,2,1}, S31:AC31)) -> 0 | AF31: =IF(AND(COUNT(C31:E31)=0,COUNT(G31:I31)=0,COUNT(K31:M31)=0,COUNT(O31:Q31)=0,COUNT(S31:AC31)=0,AE31=""),"",(IF(COUNT(C31:E31)=0,0,SUMPRODUCT({5000,1000,500},C31:E31))+IF(COUNT(G31:I31)=0,0,SUMPRODUCT({5000,1000,500},G31:I31))+IF(COUNT(K31:M31)=0,0,SUMPRODUCT({5000,1000,500},K31:M31))+IF(COUNT(O31:Q31)=0,0,SUMPRODUCT({5000,1000,500},O31:Q31))+AD31)-N(AE31)) | AG31: =IF(AF31="","",IF(AF31>0,"Excess",IF(AF31<0,"Short","Balanced"))) | AK31: =IF(AND(AI31="",AJ31=""),"",N(AI31)-N(AJ31)) | AL31: =IF(AK31="","",IF(AK31>0,"POS Excess",IF(AK31<0,"Bank Short","Matched")))
B32: =IF(A32="","",VLOOKUP(A32,'Employee Database'!A:B,2,FALSE)) | F32: =IF(COUNT(C32:E32)=0,0,SUMPRODUCT({5000,1000,500},C32:E32)) -> 0 | J32: =IF(COUNT(G32:I32)=0,0,SUMPRODUCT({5000,1000,500},G32:I32)) -> 0 | N32: =IF(COUNT(K32:M32)=0,0,SUMPRODUCT({5000,1000,500},K32:M32)) -> 0 | R32: =IF(COUNT(O32:Q32)=0,0,SUMPRODUCT({5000,1000,500},O32:Q32)) -> 0 | AD32: =IF(COUNT(S32:AC32)=0,0,SUMPRODUCT({5000,1000,500,100,75,50,20,10,5,2,1}, S32:AC32)) -> 0 | AF32: =IF(AND(COUNT(C32:E32)=0,COUNT(G32:I32)=0,COUNT(K32:M32)=0,COUNT(O32:Q32)=0,COUNT(S32:AC32)=0,AE32=""),"",(IF(COUNT(C32:E32)=0,0,SUMPRODUCT({5000,1000,500},C32:E32))+IF(COUNT(G32:I32)=0,0,SUMPRODUCT({5000,1000,500},G32:I32))+IF(COUNT(K32:M32)=0,0,SUMPRODUCT({5000,1000,500},K32:M32))+IF(COUNT(O32:Q32)=0,0,SUMPRODUCT({5000,1000,500},O32:Q32))+AD32)-N(AE32)) | AG32: =IF(AF32="","",IF(AF32>0,"Excess",IF(AF32<0,"Short","Balanced"))) | AK32: =IF(AND(AI32="",AJ32=""),"",N(AI32)-N(AJ32)) | AL32: =IF(AK32="","",IF(AK32>0,"POS Excess",IF(AK32<0,"Bank Short","Matched")))
B33: =IF(A33="","",VLOOKUP(A33,'Employee Database'!A:B,2,FALSE)) | F33: =IF(COUNT(C33:E33)=0,0,SUMPRODUCT({5000,1000,500},C33:E33)) -> 0 | J33: =IF(COUNT(G33:I33)=0,0,SUMPRODUCT({5000,1000,500},G33:I33)) -> 0 | N33: =IF(COUNT(K33:M33)=0,0,SUMPRODUCT({5000,1000,500},K33:M33)) -> 0 | R33: =IF(COUNT(O33:Q33)=0,0,SUMPRODUCT({5000,1000,500},O33:Q33)) -> 0 | AD33: =IF(COUNT(S33:AC33)=0,0,SUMPRODUCT({5000,1000,500,100,75,50,20,10,5,2,1}, S33:AC33)) -> 0 | AF33: =IF(AND(COUNT(C33:E33)=0,COUNT(G33:I33)=0,COUNT(K33:M33)=0,COUNT(O33:Q33)=0,COUNT(S33:AC33)=0,AE33=""),"",(IF(COUNT(C33:E33)=0,0,SUMPRODUCT({5000,1000,500},C33:E33))+IF(COUNT(G33:I33)=0,0,SUMPRODUCT({5000,1000,500},G33:I33))+IF(COUNT(K33:M33)=0,0,SUMPRODUCT({5000,1000,500},K33:M33))+IF(COUNT(O33:Q33)=0,0,SUMPRODUCT({5000,1000,500},O33:Q33))+AD33)-N(AE33)) | AG33: =IF(AF33="","",IF(AF33>0,"Excess",IF(AF33<0,"Short","Balanced"))) | AK33: =IF(AND(AI33="",AJ33=""),"",N(AI33)-N(AJ33)) | AL33: =IF(AK33="","",IF(AK33>0,"POS Excess",IF(AK33<0,"Bank Short","Matched")))
B34: =IF(A34="","",VLOOKUP(A34,'Employee Database'!A:B,2,FALSE)) | F34: =IF(COUNT(C34:E34)=0,0,SUMPRODUCT({5000,1000,500},C34:E34)) -> 0 | J34: =IF(COUNT(G34:I34)=0,0,SUMPRODUCT({5000,1000,500},G34:I34)) -> 0 | N34: =IF(COUNT(K34:M34)=0,0,SUMPRODUCT({5000,1000,500},K34:M34)) -> 0 | R34: =IF(COUNT(O34:Q34)=0,0,SUMPRODUCT({5000,1000,500},O34:Q34)) -> 0 | AD34: =IF(COUNT(S34:AC34)=0,0,SUMPRODUCT({5000,1000,500,100,75,50,20,10,5,2,1}, S34:AC34)) -> 0 | AF34: =IF(AND(COUNT(C34:E34)=0,COUNT(G34:I34)=0,COUNT(K34:M34)=0,COUNT(O34:Q34)=0,COUNT(S34:AC34)=0,AE34=""),"",(IF(COUNT(C34:E34)=0,0,SUMPRODUCT({5000,1000,500},C34:E34))+IF(COUNT(G34:I34)=0,0,SUMPRODUCT({5000,1000,500},G34:I34))+IF(COUNT(K34:M34)=0,0,SUMPRODUCT({5000,1000,500},K34:M34))+IF(COUNT(O34:Q34)=0,0,SUMPRODUCT({5000,1000,500},O34:Q34))+AD34)-N(AE34)) | AG34: =IF(AF34="","",IF(AF34>0,"Excess",IF(AF34<0,"Short","Balanced"))) | AK34: =IF(AND(AI34="",AJ34=""),"",N(AI34)-N(AJ34)) | AL34: =IF(AK34="","",IF(AK34>0,"POS Excess",IF(AK34<0,"Bank Short","Matched")))
A35: - | B35: - | C35: =SUM(C5:C34) -> 307 | D35: =SUM(D5:D34) -> 920 | E35: =SUM(E5:E34) -> 91 | F35: =SUM(F5:F34) -> 2500500 | G35: =SUM(G5:G34) -> 608 | H35: =SUM(H5:H34) -> 1095 | I35: =SUM(I5:I34) -> 333 | J35: =SUM(J5:J34) -> 4301500 | ... AF35: =SUM(AF5:AF34) -> 1192 | AG35: - | AH35: - | AI35: =SUM(AI5:AI34) -> 16028027 | AJ35: =SUM(AJ5:AJ34) -> 16028017 | AK35: =SUM(AK5:AK34) -> 10.73 | AL35: =AJ35+AE35 -> 22904730 | AM35: =SUM(AM5:AM34) -> 0

Sheet 2
A1: Daily Cash Collection - Lahore-4
A2: ='1'!A2+1 -> 46205
A3: Employee Details | C3: 1st Collection | G3: 2nd Collection | K3: 3rd Collection | O3: 4th Collection | S3: Fifth Collection (Closing Cash) | AD3: Closing | AH3: Settlemnet Report
A4: Emp ID | B4: Employee Name | C4: 5000 | D4: 1000 | E4: 500 | F4: Total | G4: 5000 | H4: 1000 | I4: 500 | J4: Total | K4: 5000 | L4: 1000 | M4: 500 | N4: Total | O4: 5000 | P4: 1000 | Q4: 500 | R4: Total | S4: 5000 | T4: 1000 | U4: 500 | V4: 100 | W4: 75 | X4: 50 | Y4: 20 | Z4: 10 | AA4: 5 | AB4: 2 | AC4: 1 | AD4: Total Closing Cash | AE4: System Total Sale | AF4: Collection Difference | AG4: Audit Status | AH4: Remarks | AI4: ivend Settle (POS) | AJ4: Settlement Report (Bank) | AK4: Card Difference | AL4: Card Status | AM4: Remaks
A5: 59257 | B5: =IF(A5="","",VLOOKUP(A5,'Employee Database'!A:B,2,FALSE)) -> Saddiqa Maryam | C5: 76 | D5: 114 | E5: 20 | F5: =IF(COUNT(C5:E5)=0,0,SUMPRODUCT({5000,1000,500},C5:E5)) -> 504000 | J5: =IF(COUNT(G5:I5)=0,0,SUMPRODUCT({5000,1000,500},G5:I5)) -> 0 | N5: =IF(COUNT(K5:M5)=0,0,SUMPRODUCT({5000,1000,500},K5:M5)) -> 0 | R5: =IF(COUNT(O5:Q5)=0,0,SUMPRODUCT({5000,1000,500},O5:Q5)) -> 0 | V5: 1 | X5: 32 | Z5: 22 | AD5: =IF(COUNT(S5:AC5)=0,0,SUMPRODUCT({5000,1000,500,100,75,50,20,10,5,2,1}, S5:AC5)) -> 1920 | AE5: 506105 | AF5: =IF(AND(COUNT(C5:E5)=0,COUNT(G5:I5)=0,COUNT(K5:M5)=0,COUNT(O5:Q5)=0,COUNT(S5:AC5)=0,AE5=""),"",(IF(COUNT(C5:E5)=0,0,SUMPRODUCT({5000,1000,500},C5:E5))+IF(COUNT(G5:I5)=0,0,SUMPRODUCT({5000,1000,500},G5:I5))+IF(COUNT(K5:M5)=0,0,SUMPRODUCT({5000,1000,500},K5:M5))+IF(COUNT(O5:Q5)=0,0,SUMPRODUCT({5000,1000,500},O5:Q5))+AD5)-N(AE5)) -> -185 | AG5: =IF(AF5="","",IF(AF5>0,"Excess",IF(AF5<0,"Short","Balanced"))) -> Short | AI5: 865057.98 | AJ5: =338490.16+526567.82 -> 865057.98 | AK5: =IF(AND(AI5="",AJ5=""),"",N(AI5)-N(AJ5)) -> 0 | AL5: =IF(AK5="","",IF(AK5>0,"POS Excess",IF(AK5<0,"Bank Short","Matched"))) -> Matched
A6: 58112 | B6: =IF(A6="","",VLOOKUP(A6,'Employee Database'!A:B,2,FALSE)) -> Shama | C6: 63 | D6: 232 | E6: 10 | F6: =IF(COUNT(C6:E6)=0,0,SUMPRODUCT({5000,1000,500},C6:E6)) -> 552000 | J6: =IF(COUNT(G6:I6)=0,0,SUMPRODUCT({5000,1000,500},G6:I6)) -> 0 | N6: =IF(COUNT(K6:M6)=0,0,SUMPRODUCT({5000,1000,500},K6:M6)) -> 0 | R6: =IF(COUNT(O6:Q6)=0,0,SUMPRODUCT({5000,1000,500},O6:Q6)) -> 0 | Z6: 55 | AD6: =IF(COUNT(S6:AC6)=0,0,SUMPRODUCT({5000,1000,500,100,75,50,20,10,5,2,1}, S6:AC6)) -> 550 | AE6: 552561 | AF6: =IF(AND(COUNT(C6:E6)=0,COUNT(G6:I6)=0,COUNT(K6:M6)=0,COUNT(O6:Q6)=0,COUNT(S6:AC6)=0,AE6=""),"",(IF(COUNT(C6:E6)=0,0,SUMPRODUCT({5000,1000,500},C6:E6))+IF(COUNT(G6:I6)=0,0,SUMPRODUCT({5000,1000,500},G6:I6))+IF(COUNT(K6:M6)=0,0,SUMPRODUCT({5000,1000,500},K6:M6))+IF(COUNT(O6:Q6)=0,0,SUMPRODUCT({5000,1000,500},O6:Q6))+AD6)-N(AE6)) -> -11 | AG6: =IF(AF6="","",IF(AF6>0,"Excess",IF(AF6<0,"Short","Balanced"))) -> Short | AI6: 791931.54 | AJ6: =455817.66+336113.88 -> 791931.54 | AK6: =IF(AND(AI6="",AJ6=""),"",N(AI6)-N(AJ6)) -> 0 | AL6: =IF(AK6="","",IF(AK6>0,"POS Excess",IF(AK6<0,"Bank Short","Matched"))) -> Matched
A7: 69726 | B7: =IF(A7="","",VLOOKUP(A7,'Employee Database'!A:B,2,FALSE)) -> M Arslan | C7: 17 | D7: 42 | E7: 4 | F7: =IF(COUNT(C7:E7)=0,0,SUMPRODUCT({5000,1000,500},C7:E7)) -> 129000 | J7: =IF(COUNT(G7:I7)=0,0,SUMPRODUCT({5000,1000,500},G7:I7)) -> 0 | N7: =IF(COUNT(K7:M7)=0,0,SUMPRODUCT({5000,1000,500},K7:M7)) -> 0 | R7: =IF(COUNT(O7:Q7)=0,0,SUMPRODUCT({5000,1000,500},O7:Q7)) -> 0 | X7: 3 | Z7: 44 | AD7: =IF(COUNT(S7:AC7)=0,0,SUMPRODUCT({5000,1000,500,100,75,50,20,10,5,2,1}, S7:AC7)) -> 590 | AE7: 129550 | AF7: =IF(AND(COUNT(C7:E7)=0,COUNT(G7:I7)=0,COUNT(K7:M7)=0,COUNT(O7:Q7)=0,COUNT(S7:AC7)=0,AE7=""),"",(IF(COUNT(C7:E7)=0,0,SUMPRODUCT({5000,1000,500},C7:E7))+IF(COUNT(G7:I7)=0,0,SUMPRODUCT({5000,1000,500},G7:I7))+IF(COUNT(K7:M7)=0,0,SUMPRODUCT({5000,1000,500},K7:M7))+IF(COUNT(O7:Q7)=0,0,SUMPRODUCT({5000,1000,500},O7:Q7))+AD7)-N(AE7)) -> 40 | AG7: =IF(AF7="","",IF(AF7>0,"Excess",IF(AF7<0,"Short","Balanced"))) -> Excess | AI7: 257699.68 | AJ7: 257699.68 | AK7: =IF(AND(AI7="",AJ7=""),"",N(AI7)-N(AJ7)) -> 0 | AL7: =IF(AK7="","",IF(AK7>0,"POS Excess",IF(AK7<0,"Bank Short","Matched"))) -> Matched
A8: 63854 | B8: =IF(A8="","",VLOOKUP(A8,'Employee Database'!A:B,2,FALSE)) -> Maham | C8: 3 | D8: 19 | E8: 4 | F8: =IF(COUNT(C8:E8)=0,0,SUMPRODUCT({5000,1000,500},C8:E8)) -> 36000 | J8: =IF(COUNT(G8:I8)=0,0,SUMPRODUCT({5000,1000,500},G8:I8)) -> 0 | N8: =IF(COUNT(K8:M8)=0,0,SUMPRODUCT({5000,1000,500},K8:M8)) -> 0 | R8: =IF(COUNT(O8:Q8)=0,0,SUMPRODUCT({5000,1000,500},O8:Q8)) -> 0 | X8: 8 | Z8: 12 | AD8: =IF(COUNT(S8:AC8)=0,0,SUMPRODUCT({5000,1000,500,100,75,50,20,10,5,2,1}, S8:AC8)) -> 520 | AE8: 36483 | AF8: =IF(AND(COUNT(C8:E8)=0,COUNT(G8:I8)=0,COUNT(K8:M8)=0,COUNT(O8:Q8)=0,COUNT(S8:AC8)=0,AE8=""),"",(IF(COUNT(C8:E8)=0,0,SUMPRODUCT({5000,1000,500},C8:E8))+IF(COUNT(G8:I8)=0,0,SUMPRODUCT({5000,1000,500},G8:I8))+IF(COUNT(K8:M8)=0,0,SUMPRODUCT({5000,1000,500},K8:M8))+IF(COUNT(O8:Q8)=0,0,SUMPRODUCT({5000,1000,500},O8:Q8))+AD8)-N(AE8)) -> 37 | AG8: =IF(AF8="","",IF(AF8>0,"Excess",IF(AF8<0,"Short","Balanced"))) -> Excess | AI8: 50144.49 | AJ8: =40719.05+9425.44 -> 50144.49 | AK8: =IF(AND(AI8="",AJ8=""),"",N(AI8)-N(AJ8)) -> -7.2759576e-12 | AL8: =IF(AK8="","",IF(AK8>0,"POS Excess",IF(AK8<0,"Bank Short","Matched"))) -> Bank Short
A9: 76411 | B9: =IF(A9="","",VLOOKUP(A9,'Employee Database'!A:B,2,FALSE)) -> Zubair | C9: 68 | D9: 144 | E9: 18 | F9: =IF(COUNT(C9:E9)=0,0,SUMPRODUCT({5000,1000,500},C9:E9)) -> 493000 | J9: =IF(COUNT(G9:I9)=0,0,SUMPRODUCT({5000,1000,500},G9:I9)) -> 0 | N9: =IF(COUNT(K9:M9)=0,0,SUMPRODUCT({5000,1000,500},K9:M9)) -> 0 | R9: =IF(COUNT(O9:Q9)=0,0,SUMPRODUCT({5000,1000,500},O9:Q9)) -> 0 | X9: 3 | Z9: 9 | AD9: =IF(COUNT(S9:AC9)=0,0,SUMPRODUCT({5000,1000,500,100,75,50,20,10,5,2,1}, S9:AC9)) -> 240 | AE9: 493195 | AF9: =IF(AND(COUNT(C9:E9)=0,COUNT(G9:I9)=0,COUNT(K9:M9)=0,COUNT(O9:Q9)=0,COUNT(S9:AC9)=0,AE9=""),"",(IF(COUNT(C9:E9)=0,0,SUMPRODUCT({5000,1000,500},C9:E9))+IF(COUNT(G9:I9)=0,0,SUMPRODUCT({5000,1000,500},G9:I9))+IF(COUNT(K9:M9)=0,0,SUMPRODUCT({5000,1000,500},K9:M9))+IF(COUNT(O9:Q9)=0,0,SUMPRODUCT({5000,1000,500},O9:Q9))+AD9)-N(AE9)) -> 45 | AG9: =IF(AF9="","",IF(AF9>0,"Excess",IF(AF9<0,"Short","Balanced"))) -> Excess | AI9: =308733.47+342758.45 -> 651491.92 | AJ9: =342758.45+308733.47 -> 651491.92 | AK9: =IF(AND(AI9="",AJ9=""),"",N(AI9)-N(AJ9)) -> 0 | AL9: =IF(AK9="","",IF(AK9>0,"POS Excess",IF(AK9<0,"Bank Short","Matched"))) -> Matched
A10: 77423 | B10: =IF(A10="","",VLOOKUP(A10,'Employee Database'!A:B,2,FALSE)) -> Shoaib Akhtar | C10: 53 | D10: 139 | E10: 49 | F10: =IF(COUNT(C10:E10)=0,0,SUMPRODUCT({5000,1000,500},C10:E10)) -> 428500 | J10: =IF(COUNT(G10:I10)=0,0,SUMPRODUCT({5000,1000,500},G10:I10)) -> 0 | N10: =IF(COUNT(K10:M10)=0,0,SUMPRODUCT({5000,1000,500},K10:M10)) -> 0 | R10: =IF(COUNT(O10:Q10)=0,0,SUMPRODUCT({5000,1000,500},O10:Q10)) -> 0 | X10: 10 | Z10: 80 | AD10: =IF(COUNT(S10:AC10)=0,0,SUMPRODUCT({5000,1000,500,100,75,50,20,10,5,2,1}, S10:AC10)) -> 1300 | AE10: 429977 | AF10: =IF(AND(COUNT(C10:E10)=0,COUNT(G10:I10)=0,COUNT(K10:M10)=0,COUNT(O10:Q10)=0,COUNT(S10:AC10)=0,AE10=""),"",(IF(COUNT(C10:E10)=0,0,SUMPRODUCT({5000,1000,500},C10:E10))+IF(COUNT(G10:I10)=0,0,SUMPRODUCT({5000,1000,500},G10:I10))+IF(COUNT(K10:M10)=0,0,SUMPRODUCT({5000,1000,500},K10:M10))+IF(COUNT(O10:Q10)=0,0,SUMPRODUCT({5000,1000,500},O10:Q10))+AD10)-N(AE10)) -> -177 | AG10: =IF(AF10="","",IF(AF10>0,"Excess",IF(AF10<0,"Short","Balanced"))) -> Short | AI10: 871565.17 | AJ10: =543208.14+328357.03 -> 871565.17 | AK10: =IF(AND(AI10="",AJ10=""),"",N(AI10)-N(AJ10)) -> 0 | AL10: =IF(AK10="","",IF(AK10>0,"POS Excess",IF(AK10<0,"Bank Short","Matched"))) -> Matched
A11: 68107 | B11: =IF(A11="","",VLOOKUP(A11,'Employee Database'!A:B,2,FALSE)) -> M Harris | C11: 26 | D11: 17 | E11: 0 | F11: =IF(COUNT(C11:E11)=0,0,SUMPRODUCT({5000,1000,500},C11:E11)) -> 147000 | J11: =IF(COUNT(G11:I11)=0,0,SUMPRODUCT({5000,1000,500},G11:I11)) -> 0 | N11: =IF(COUNT(K11:M11)=0,0,SUMPRODUCT({5000,1000,500},K11:M11)) -> 0 | R11: =IF(COUNT(O11:Q11)=0,0,SUMPRODUCT({5000,1000,500},O11:Q11)) -> 0 | X11: 8 | Y11: 1 | Z11: 28 | AD11: =IF(COUNT(S11:AC11)=0,0,SUMPRODUCT({5000,1000,500,100,75,50,20,10,5,2,1}, S11:AC11)) -> 700 | AE11: 147772 | AF11: =IF(AND(COUNT(C11:E11)=0,COUNT(G11:I11)=0,COUNT(K11:M11)=0,COUNT(O11:Q11)=0,COUNT(S11:AC11)=0,AE11=""),"",(IF(COUNT(C11:E11)=0,0,SUMPRODUCT({5000,1000,500},C11:E11))+IF(COUNT(G11:I11)=0,0,SUMPRODUCT({5000,1000,500},G11:I11))+IF(COUNT(K11:M11)=0,0,SUMPRODUCT({5000,1000,500},K11:M11))+IF(COUNT(O11:Q11)=0,0,SUMPRODUCT({5000,1000,500},O11:Q11))+AD11)-N(AE11)) -> -72 | AG11: =IF(AF11="","",IF(AF11>0,"Excess",IF(AF11<0,"Short","Balanced"))) -> Short | AI11: 135064 | AJ11: =85046.34+50017.84 -> 135064.18 | AK11: =IF(AND(AI11="",AJ11=""),"",N(AI11)-N(AJ11)) -> -0.18 | AL11: =IF(AK11="","",IF(AK11>0,"POS Excess",IF(AK11<0,"Bank Short","Matched"))) -> Bank Short
A12: 67249 | B12: =IF(A12="","",VLOOKUP(A12,'Employee Database'!A:B,2,FALSE)) -> Hanan Javaid | C12: 43 | D12: 155 | E12: 26 | F12: =IF(COUNT(C12:E12)=0,0,SUMPRODUCT({5000,1000,500},C12:E12)) -> 383000 | J12: =IF(COUNT(G12:I12)=0,0,SUMPRODUCT({5000,1000,500},G12:I12)) -> 0 | N12: =IF(COUNT(K12:M12)=0,0,SUMPRODUCT({5000,1000,500},K12:M12)) -> 0 | R12: =IF(COUNT(O12:Q12)=0,0,SUMPRODUCT({5000,1000,500},O12:Q12)) -> 0 | X12: 93 | Z12: 9 | AD12: =IF(COUNT(S12:AC12)=0,0,SUMPRODUCT({5000,1000,500,100,75,50,20,10,5,2,1}, S12:AC12)) -> 4740 | AE12: 387768 | AF12: =IF(AND(COUNT(C12:E12)=0,COUNT(G12:I12)=0,COUNT(K12:M12)=0,COUNT(O12:Q12)=0,COUNT(S12:AC12)=0,AE12=""),"",(IF(COUNT(C12:E12)=0,0,SUMPRODUCT({5000,1000,500},C12:E12))+IF(COUNT(G12:I12)=0,0,SUMPRODUCT({5000,1000,500},G12:I12))+IF(COUNT(K12:M12)=0,0,SUMPRODUCT({5000,1000,500},K12:M12))+IF(COUNT(O12:Q12)=0,0,SUMPRODUCT({5000,1000,500},O12:Q12))+AD12)-N(AE12)) -> -28 | AG12: =IF(AF12="","",IF(AF12>0,"Excess",IF(AF12<0,"Short","Balanced"))) -> Short | AI12: =257058.26+9618.53 -> 266676.79 | AJ12: =112745.51+144312.75+9618.53 -> 266676.79 | AK12: =IF(AND(AI12="",AJ12=""),"",N(AI12)-N(AJ12)) -> 0 | AL12: =IF(AK12="","",IF(AK12>0,"POS Excess",IF(AK12<0,"Bank Short","Matched"))) -> Matched
A13: 50313 | B13: =IF(A13="","",VLOOKUP(A13,'Employee Database'!A:B,2,FALSE)) -> Waseem Raza | C13: 11 | D13: 105 | F13: =IF(COUNT(C13:E13)=0,0,SUMPRODUCT({5000,1000,500},C13:E13)) -> 160000 | H13: 2 | J13: =IF(COUNT(G13:I13)=0,0,SUMPRODUCT({5000,1000,500},G13:I13)) -> 2000 | N13: =IF(COUNT(K13:M13)=0,0,SUMPRODUCT({5000,1000,500},K13:M13)) -> 0 | R13: =IF(COUNT(O13:Q13)=0,0,SUMPRODUCT({5000,1000,500},O13:Q13)) -> 0 | X13: 26 | Z13: 5 | AD13: =IF(COUNT(S13:AC13)=0,0,SUMPRODUCT({5000,1000,500,100,75,50,20,10,5,2,1}, S13:AC13)) -> 1350 | AE13: 163359 | AF13: =IF(AND(COUNT(C13:E13)=0,COUNT(G13:I13)=0,COUNT(K13:M13)=0,COUNT(O13:Q13)=0,COUNT(S13:AC13)=0,AE13=""),"",(IF(COUNT(C13:E13)=0,0,SUMPRODUCT({5000,1000,500},C13:E13))+IF(COUNT(G13:I13)=0,0,SUMPRODUCT({5000,1000,500},G13:I13))+IF(COUNT(K13:M13)=0,0,SUMPRODUCT({5000,1000,500},K13:M13))+IF(COUNT(O13:Q13)=0,0,SUMPRODUCT({5000,1000,500},O13:Q13))+AD13)-N(AE13)) -> -9 | AG13: =IF(AF13="","",IF(AF13>0,"Excess",IF(AF13<0,"Short","Balanced"))) -> Short | AI13: 215996.15 | AJ13: 215996.15 | AK13: =IF(AND(AI13="",AJ13=""),"",N(AI13)-N(AJ13)) -> 0 | AL13: =IF(AK13="","",IF(AK13>0,"POS Excess",IF(AK13<0,"Bank Short","Matched"))) -> Matched
A14: 69732 | B14: =IF(A14="","",VLOOKUP(A14,'Employee Database'!A:B,2,FALSE)) -> Abdul Hafeez | F14: =IF(COUNT(C14:E14)=0,0,SUMPRODUCT({5000,1000,500},C14:E14)) -> 0 | G14: 20 | H14: 37 | I14: 6 | J14: =IF(COUNT(G14:I14)=0,0,SUMPRODUCT({5000,1000,500},G14:I14)) -> 140000 | N14: =IF(COUNT(K14:M14)=0,0,SUMPRODUCT({5000,1000,500},K14:M14)) -> 0 | R14: =IF(COUNT(O14:Q14)=0,0,SUMPRODUCT({5000,1000,500},O14:Q14)) -> 0 | X14: 15 | Z14: 12 | AD14: =IF(COUNT(S14:AC14)=0,0,SUMPRODUCT({5000,1000,500,100,75,50,20,10,5,2,1}, S14:AC14)) -> 870 | AE14: 140839 | AF14: =IF(AND(COUNT(C14:E14)=0,COUNT(G14:I14)=0,COUNT(K14:M14)=0,COUNT(O14:Q14)=0,COUNT(S14:AC14)=0,AE14=""),"",(IF(COUNT(C14:E14)=0,0,SUMPRODUCT({5000,1000,500},C14:E14))+IF(COUNT(G14:I14)=0,0,SUMPRODUCT({5000,1000,500},G14:I14))+IF(COUNT(K14:M14)=0,0,SUMPRODUCT({5000,1000,500},K14:M14))+IF(COUNT(O14:Q14)=0,0,SUMPRODUCT({5000,1000,500},O14:Q14))+AD14)-N(AE14)) -> 31 | AG14: =IF(AF14="","",IF(AF14>0,"Excess",IF(AF14<0,"Short","Balanced"))) -> Excess | AI14: 437728.37 | AJ14: =329588.43+108139.94 -> 437728.37 | AK14: =IF(AND(AI14="",AJ14=""),"",N(AI14)-N(AJ14)) -> 0 | AL14: =IF(AK14="","",IF(AK14>0,"POS Excess",IF(AK14<0,"Bank Short","Matched"))) -> Matched
A15: 67250 | B15: =IF(A15="","",VLOOKUP(A15,'Employee Database'!A:B,2,FALSE)) -> M Fiaz | F15: =IF(COUNT(C15:E15)=0,0,SUMPRODUCT({5000,1000,500},C15:E15)) -> 0 | G15: 45 | H15: 240 | I15: 43 | J15: =IF(COUNT(G15:I15)=0,0,SUMPRODUCT({5000,1000,500},G15:I15)) -> 486500 | N15: =IF(COUNT(K15:M15)=0,0,SUMPRODUCT({5000,1000,500},K15:M15)) -> 0 | R15: =IF(COUNT(O15:Q15)=0,0,SUMPRODUCT({5000,1000,500},O15:Q15)) -> 0 | X15: 26 | Z15: 14 | AD15: =IF(COUNT(S15:AC15)=0,0,SUMPRODUCT({5000,1000,500,100,75,50,20,10,5,2,1}, S15:AC15)) -> 1440 | AE15: 487951 | AF15: =IF(AND(COUNT(C15:E15)=0,COUNT(G15:I15)=0,COUNT(K15:M15)=0,COUNT(O15:Q15)=0,COUNT(S15:AC15)=0,AE15=""),"",(IF(COUNT(C15:E15)=0,0,SUMPRODUCT({5000,1000,500},C15:E15))+IF(COUNT(G15:I15)=0,0,SUMPRODUCT({5000,1000,500},G15:I15))+IF(COUNT(K15:M15)=0,0,SUMPRODUCT({5000,1000,500},K15:M15))+IF(COUNT(O15:Q15)=0,0,SUMPRODUCT({5000,1000,500},O15:Q15))+AD15)-N(AE15)) -> -11 | AG15: =IF(AF15="","",IF(AF15>0,"Excess",IF(AF15<0,"Short","Balanced"))) -> Short | AI15: 898045.99 | AJ15: 898045.99 | AK15: =IF(AND(AI15="",AJ15=""),"",N(AI15)-N(AJ15)) -> 0 | AL15: =IF(AK15="","",IF(AK15>0,"POS Excess",IF(AK15<0,"Bank Short","Matched"))) -> Matched
A16: 50134 | B16: =IF(A16="","",VLOOKUP(A16,'Employee Database'!A:B,2,FALSE)) -> Asif Abbas | F16: =IF(COUNT(C16:E16)=0,0,SUMPRODUCT({5000,1000,500},C16:E16)) -> 0 | G16: 18 | H16: 124 | I16: 0 | J16: =IF(COUNT(G16:I16)=0,0,SUMPRODUCT({5000,1000,500},G16:I16)) -> 214000 | N16: =IF(COUNT(K16:M16)=0,0,SUMPRODUCT({5000,1000,500},K16:M16)) -> 0 | R16: =IF(COUNT(O16:Q16)=0,0,SUMPRODUCT({5000,1000,500},O16:Q16)) -> 0 | V16: 4 | X16: 46 | Z16: 77 | AD16: =IF(COUNT(S16:AC16)=0,0,SUMPRODUCT({5000,1000,500,100,75,50,20,10,5,2,1}, S16:AC16)) -> 3470 | AE16: 217470 | AF16: =IF(AND(COUNT(C16:E16)=0,COUNT(G16:I16)=0,COUNT(K16:M16)=0,COUNT(O16:Q16)=0,COUNT(S16:AC16)=0,AE16=""),"",(IF(COUNT(C16:E16)=0,0,SUMPRODUCT({5000,1000,500},C16:E16))+IF(COUNT(G16:I16)=0,0,SUMPRODUCT({5000,1000,500},G16:I16))+IF(COUNT(K16:M16)=0,0,SUMPRODUCT({5000,1000,500},K16:M16))+IF(COUNT(O16:Q16)=0,0,SUMPRODUCT({5000,1000,500},O16:Q16))+AD16)-N(AE16)) -> 0 | AG16: =IF(AF16="","",IF(AF16>0,"Excess",IF(AF16<0,"Short","Balanced"))) -> Balanced | AI16: 448080.74 | AJ16: 448080.74 | AK16: =IF(AND(AI16="",AJ16=""),"",N(AI16)-N(AJ16)) -> 0 | AL16: =IF(AK16="","",IF(AK16>0,"POS Excess",IF(AK16<0,"Bank Short","Matched"))) -> Matched
