Workbook

Sheet Search
A1: RETURN TRANSACTION SEARCH
A3: Select Day | B3: 1
A4: Search By | B4: Trx No
A5: Enter Number | B5: xxx
A8: S.No. | B8: Customer Name | C8: Contact No | D8: Return Trx | E8: Trx No | F8: Item Description | G8: Item Exp Date | H8: Qty | I8: Total Amount | J8: Reason | K8: Approval Name | L8: Designation | M8: System Status | N8: Cash/Voucher | O8: Rcv by | P8: CCTV/Time | Q8: Trx Time
A9: =IF($B$5="","",IFERROR(INDEX(INDIRECT("'"&$B$3&"'!$A$2:$Q$201"),MATCH($B$5,INDIRECT("'"&$B$3&"'!"&IF($B$4="Return Trx","$D$2:$D$201","$E$2:$E$201")),0),1),"Not Found")) -> Not Found | B9: =IF($B$5="","",IFERROR(INDEX(INDIRECT("'"&$B$3&"'!$A$2:$Q$201"),MATCH($B$5,INDIRECT("'"&$B$3&"'!"&IF($B$4="Return Trx","$D$2:$D$201","$E$2:$E$201")),0),2),"Not Found")) -> Not Found | C9: =IF($B$5="","",IFERROR(INDEX(INDIRECT("'"&$B$3&"'!$A$2:$Q$201"),MATCH($B$5,INDIRECT("'"&$B$3&"'!"&IF($B$4="Return Trx","$D$2:$D$201","$E$2:$E$201")),0),3),"Not Found")) -> Not Found | D9: =IF($B$5="","",IFERROR(INDEX(INDIRECT("'"&$B$3&"'!$A$2:$Q$201"),MATCH($B$5,INDIRECT("'"&$B$3&"'!"&IF($B$4="Return Trx","$D$2:$D$201","$E$2:$E$201")),0),4),"Not Found")) -> Not Found | E9: =IF($B$5="","",IFERROR(INDEX(INDIRECT("'"&$B$3&"'!$A$2:$Q$201"),MATCH($B$5,INDIRECT("'"&$B$3&"'!"&IF($B$4="Return Trx","$D$2:$D$201","$E$2:$E$201")),0),5),"Not Found")) -> Not Found | F9: =IF($B$5="","",IFERROR(INDEX(INDIRECT("'"&$B$3&"'!$A$2:$Q$201"),MATCH($B$5,INDIRECT("'"&$B$3&"'!"&IF($B$4="Return Trx","$D$2:$D$201","$E$2:$E$201")),0),6),"Not Found")) -> Not Found | G9: =IF($B$5="","",IFERROR(INDEX(INDIRECT("'"&$B$3&"'!$A$2:$Q$201"),MATCH($B$5,INDIRECT("'"&$B$3&"'!"&IF($B$4="Return Trx","$D$2:$D$201","$E$2:$E$201")),0),7),"Not Found")) -> Not Found | H9: =IF($B$5="","",IFERROR(INDEX(INDIRECT("'"&$B$3&"'!$A$2:$Q$201"),MATCH($B$5,INDIRECT("'"&$B$3&"'!"&IF($B$4="Return Trx","$D$2:$D$201","$E$2:$E$201")),0),8),"Not Found")) -> Not Found | I9: =IF($B$5="","",IFERROR(INDEX(INDIRECT("'"&$B$3&"'!$A$2:$Q$201"),MATCH($B$5,INDIRECT("'"&$B$3&"'!"&IF($B$4="Return Trx","$D$2:$D$201","$E$2:$E$201")),0),9),"Not Found")) -> Not Found | J9: =IF($B$5="","",IFERROR(INDEX(INDIRECT("'"&$B$3&"'!$A$2:$Q$201"),MATCH($B$5,INDIRECT("'"&$B$3&"'!"&IF($B$4="Return Trx","$D$2:$D$201","$E$2:$E$201")),0),10),"Not Found")) -> Not Found | K9: =IF($B$5="","",IFERROR(INDEX(INDIRECT("'"&$B$3&"'!$A$2:$Q$201"),MATCH($B$5,INDIRECT("'"&$B$3&"'!"&IF($B$4="Return Trx","$D$2:$D$201","$E$2:$E$201")),0),11),"Not Found")) -> Not Found | L9: =IF($B$5="","",IFERROR(INDEX(INDIRECT("'"&$B$3&"'!$A$2:$Q$201"),MATCH($B$5,INDIRECT("'"&$B$3&"'!"&IF($B$4="Return Trx","$D$2:$D$201","$E$2:$E$201")),0),12),"Not Found")) -> Not Found | M9: =IF($B$5="","",IFERROR(INDEX(INDIRECT("'"&$B$3&"'!$A$2:$Q$201"),MATCH($B$5,INDIRECT("'"&$B$3&"'!"&IF($B$4="Return Trx","$D$2:$D$201","$E$2:$E$201")),0),13),"Not Found")) -> Not Found | N9: =IF($B$5="","",IFERROR(INDEX(INDIRECT("'"&$B$3&"'!$A$2:$Q$201"),MATCH($B$5,INDIRECT("'"&$B$3&"'!"&IF($B$4="Return Trx","$D$2:$D$201","$E$2:$E$201")),0),14),"Not Found")) -> Not Found | O9: =IF($B$5="","",IFERROR(INDEX(INDIRECT("'"&$B$3&"'!$A$2:$Q$201"),MATCH($B$5,INDIRECT("'"&$B$3&"'!"&IF($B$4="Return Trx","$D$2:$D$201","$E$2:$E$201")),0),15),"Not Found")) -> Not Found | P9: =IF($B$5="","",IFERROR(INDEX(INDIRECT("'"&$B$3&"'!$A$2:$Q$201"),MATCH($B$5,INDIRECT("'"&$B$3&"'!"&IF($B$4="Return Trx","$D$2:$D$201","$E$2:$E$201")),0),16),"Not Found")) -> Not Found | Q9: =IF($B$5="","",IFERROR(INDEX(INDIRECT("'"&$B$3&"'!$A$2:$Q$201"),MATCH($B$5,INDIRECT("'"&$B$3&"'!"&IF($B$4="Return Trx","$D$2:$D$201","$E$2:$E$201")),0),17),"Not Found")) -> Not Found

Sheet Dashboard
A1: RETURN APPROVAL – DAY WISE DASHBOARD | K1: MONTHLY RETURN CONTROL
A3: Day | B3: Cash Amount | C3: Voucher Amount | D3: Total Return Amount | E3: Valid Approval Amount | F3: Limit Exceeded Amount | G3: Valid Approval Count | H3: Limit Exceeded Count | I3: Total Entries
A4: 1 | B4: =SUMIF('1'!$N$2:$N$201,"CASH",'1'!$I$2:$I$201) -> 0 | C4: =SUMIF('1'!$N$2:$N$201,"VOUCHER",'1'!$I$2:$I$201) -> 0 | D4: =SUM('1'!$I$2:$I$201) -> 0 | E4: =SUMIF('1'!$M$2:$M$201,"Valid Approval",'1'!$I$2:$I$201) -> 0 | F4: =SUMIF('1'!$M$2:$M$201,"Limit Exceeded",'1'!$I$2:$I$201) -> 0 | G4: =COUNTIF('1'!$M$2:$M$201,"Valid Approval") -> 0 | H4: =COUNTIF('1'!$M$2:$M$201,"Limit Exceeded") -> 0 | I4: =COUNTA('1'!$D$2:$D$201) -> 0 | K4: KPI | L4: Value
A5: 2 | B5: =SUMIF('2'!$N$2:$N$201,"CASH",'2'!$I$2:$I$201) -> 0 | C5: =SUMIF('2'!$N$2:$N$201,"VOUCHER",'2'!$I$2:$I$201) -> 0 | D5: =SUM('2'!$I$2:$I$201) -> 0 | E5: =SUMIF('2'!$M$2:$M$201,"Valid Approval",'2'!$I$2:$I$201) -> 0 | F5: =SUMIF('2'!$M$2:$M$201,"Limit Exceeded",'2'!$I$2:$I$201) -> 0 | G5: =COUNTIF('2'!$M$2:$M$201,"Valid Approval") -> 0 | H5: =COUNTIF('2'!$M$2:$M$201,"Limit Exceeded") -> 0 | I5: =COUNTA('2'!$D$2:$D$201) -> 0 | K5: Cash Total | L5: =B35 -> 0
A6: 3 | B6: =SUMIF('3'!$N$2:$N$201,"CASH",'3'!$I$2:$I$201) -> 0 | C6: =SUMIF('3'!$N$2:$N$201,"VOUCHER",'3'!$I$2:$I$201) -> 0 | D6: =SUM('3'!$I$2:$I$201) -> 0 | E6: =SUMIF('3'!$M$2:$M$201,"Valid Approval",'3'!$I$2:$I$201) -> 0 | F6: =SUMIF('3'!$M$2:$M$201,"Limit Exceeded",'3'!$I$2:$I$201) -> 0 | G6: =COUNTIF('3'!$M$2:$M$201,"Valid Approval") -> 0 | H6: =COUNTIF('3'!$M$2:$M$201,"Limit Exceeded") -> 0 | I6: =COUNTA('3'!$D$2:$D$201) -> 0 | K6: Voucher Total | L6: =C35 -> 0
A7: 4 | B7: =SUMIF('4'!$N$2:$N$201,"CASH",'4'!$I$2:$I$201) -> 0 | C7: =SUMIF('4'!$N$2:$N$201,"VOUCHER",'4'!$I$2:$I$201) -> 0 | D7: =SUM('4'!$I$2:$I$201) -> 0 | E7: =SUMIF('4'!$M$2:$M$201,"Valid Approval",'4'!$I$2:$I$201) -> 0 | F7: =SUMIF('4'!$M$2:$M$201,"Limit Exceeded",'4'!$I$2:$I$201) -> 0 | G7: =COUNTIF('4'!$M$2:$M$201,"Valid Approval") -> 0 | H7: =COUNTIF('4'!$M$2:$M$201,"Limit Exceeded") -> 0 | I7: =COUNTA('4'!$D$2:$D$201) -> 0 | K7: Valid Approval | L7: =E35 -> 0
A8: 5 | B8: =SUMIF('5'!$N$2:$N$201,"CASH",'5'!$I$2:$I$201) -> 0 | C8: =SUMIF('5'!$N$2:$N$201,"VOUCHER",'5'!$I$2:$I$201) -> 0 | D8: =SUM('5'!$I$2:$I$201) -> 0 | E8: =SUMIF('5'!$M$2:$M$201,"Valid Approval",'5'!$I$2:$I$201) -> 0 | F8: =SUMIF('5'!$M$2:$M$201,"Limit Exceeded",'5'!$I$2:$I$201) -> 0 | G8: =COUNTIF('5'!$M$2:$M$201,"Valid Approval") -> 0 | H8: =COUNTIF('5'!$M$2:$M$201,"Limit Exceeded") -> 0 | I8: =COUNTA('5'!$D$2:$D$201) -> 0 | K8: Limit Exceeded | L8: =F35 -> 0
A9: 6 | B9: =SUMIF('6'!$N$2:$N$201,"CASH",'6'!$I$2:$I$201) -> 0 | C9: =SUMIF('6'!$N$2:$N$201,"VOUCHER",'6'!$I$2:$I$201) -> 0 | D9: =SUM('6'!$I$2:$I$201) -> 0 | E9: =SUMIF('6'!$M$2:$M$201,"Valid Approval",'6'!$I$2:$I$201) -> 0 | F9: =SUMIF('6'!$M$2:$M$201,"Limit Exceeded",'6'!$I$2:$I$201) -> 0 | G9: =COUNTIF('6'!$M$2:$M$201,"Valid Approval") -> 0 | H9: =COUNTIF('6'!$M$2:$M$201,"Limit Exceeded") -> 0 | I9: =COUNTA('6'!$D$2:$D$201) -> 0
A10: 7 | B10: =SUMIF('7'!$N$2:$N$201,"CASH",'7'!$I$2:$I$201) -> 0 | C10: =SUMIF('7'!$N$2:$N$201,"VOUCHER",'7'!$I$2:$I$201) -> 0 | D10: =SUM('7'!$I$2:$I$201) -> 0 | E10: =SUMIF('7'!$M$2:$M$201,"Valid Approval",'7'!$I$2:$I$201) -> 0 | F10: =SUMIF('7'!$M$2:$M$201,"Limit Exceeded",'7'!$I$2:$I$201) -> 0 | G10: =COUNTIF('7'!$M$2:$M$201,"Valid Approval") -> 0 | H10: =COUNTIF('7'!$M$2:$M$201,"Limit Exceeded") -> 0 | I10: =COUNTA('7'!$D$2:$D$201) -> 0
A11: 8 | B11: =SUMIF('8'!$N$2:$N$201,"CASH",'8'!$I$2:$I$201) -> 0 | C11: =SUMIF('8'!$N$2:$N$201,"VOUCHER",'8'!$I$2:$I$201) -> 0 | D11: =SUM('8'!$I$2:$I$201) -> 0 | E11: =SUMIF('8'!$M$2:$M$201,"Valid Approval",'8'!$I$2:$I$201) -> 0 | F11: =SUMIF('8'!$M$2:$M$201,"Limit Exceeded",'8'!$I$2:$I$201) -> 0 | G11: =COUNTIF('8'!$M$2:$M$201,"Valid Approval") -> 0 | H11: =COUNTIF('8'!$M$2:$M$201,"Limit Exceeded") -> 0 | I11: =COUNTA('8'!$D$2:$D$201) -> 0
A12: 9 | B12: =SUMIF('9'!$N$2:$N$201,"CASH",'9'!$I$2:$I$201) -> 0 | C12: =SUMIF('9'!$N$2:$N$201,"VOUCHER",'9'!$I$2:$I$201) -> 0 | D12: =SUM('9'!$I$2:$I$201) -> 0 | E12: =SUMIF('9'!$M$2:$M$201,"Valid Approval",'9'!$I$2:$I$201) -> 0 | F12: =SUMIF('9'!$M$2:$M$201,"Limit Exceeded",'9'!$I$2:$I$201) -> 0 | G12: =COUNTIF('9'!$M$2:$M$201,"Valid Approval") -> 0 | H12: =COUNTIF('9'!$M$2:$M$201,"Limit Exceeded") -> 0 | I12: =COUNTA('9'!$D$2:$D$201) -> 0
A13: 10 | B13: =SUMIF('10'!$N$2:$N$201,"CASH",'10'!$I$2:$I$201) -> 0 | C13: =SUMIF('10'!$N$2:$N$201,"VOUCHER",'10'!$I$2:$I$201) -> 0 | D13: =SUM('10'!$I$2:$I$201) -> 0 | E13: =SUMIF('10'!$M$2:$M$201,"Valid Approval",'10'!$I$2:$I$201) -> 0 | F13: =SUMIF('10'!$M$2:$M$201,"Limit Exceeded",'10'!$I$2:$I$201) -> 0 | G13: =COUNTIF('10'!$M$2:$M$201,"Valid Approval") -> 0 | H13: =COUNTIF('10'!$M$2:$M$201,"Limit Exceeded") -> 0 | I13: =COUNTA('10'!$D$2:$D$201) -> 0
A14: 11 | B14: =SUMIF('11'!$N$2:$N$201,"CASH",'11'!$I$2:$I$201) -> 0 | C14: =SUMIF('11'!$N$2:$N$201,"VOUCHER",'11'!$I$2:$I$201) -> 0 | D14: =SUM('11'!$I$2:$I$201) -> 0 | E14: =SUMIF('11'!$M$2:$M$201,"Valid Approval",'11'!$I$2:$I$201) -> 0 | F14: =SUMIF('11'!$M$2:$M$201,"Limit Exceeded",'11'!$I$2:$I$201) -> 0 | G14: =COUNTIF('11'!$M$2:$M$201,"Valid Approval") -> 0 | H14: =COUNTIF('11'!$M$2:$M$201,"Limit Exceeded") -> 0 | I14: =COUNTA('11'!$D$2:$D$201) -> 0
A15: 12 | B15: =SUMIF('12'!$N$2:$N$201,"CASH",'12'!$I$2:$I$201) -> 0 | C15: =SUMIF('12'!$N$2:$N$201,"VOUCHER",'12'!$I$2:$I$201) -> 0 | D15: =SUM('12'!$I$2:$I$201) -> 0 | E15: =SUMIF('12'!$M$2:$M$201,"Valid Approval",'12'!$I$2:$I$201) -> 0 | F15: =SUMIF('12'!$M$2:$M$201,"Limit Exceeded",'12'!$I$2:$I$201) -> 0 | G15: =COUNTIF('12'!$M$2:$M$201,"Valid Approval") -> 0 | H15: =COUNTIF('12'!$M$2:$M$201,"Limit Exceeded") -> 0 | I15: =COUNTA('12'!$D$2:$D$201) -> 0
A16: 13 | B16: =SUMIF('13'!$N$2:$N$201,"CASH",'13'!$I$2:$I$201) -> 0 | C16: =SUMIF('13'!$N$2:$N$201,"VOUCHER",'13'!$I$2:$I$201) -> 0 | D16: =SUM('13'!$I$2:$I$201) -> 0 | E16: =SUMIF('13'!$M$2:$M$201,"Valid Approval",'13'!$I$2:$I$201) -> 0 | F16: =SUMIF('13'!$M$2:$M$201,"Limit Exceeded",'13'!$I$2:$I$201) -> 0 | G16: =COUNTIF('13'!$M$2:$M$201,"Valid Approval") -> 0 | H16: =COUNTIF('13'!$M$2:$M$201,"Limit Exceeded") -> 0 | I16: =COUNTA('13'!$D$2:$D$201) -> 0
A17: 14 | B17: =SUMIF('14'!$N$2:$N$201,"CASH",'14'!$I$2:$I$201) -> 0 | C17: =SUMIF('14'!$N$2:$N$201,"VOUCHER",'14'!$I$2:$I$201) -> 0 | D17: =SUM('14'!$I$2:$I$201) -> 0 | E17: =SUMIF('14'!$M$2:$M$201,"Valid Approval",'14'!$I$2:$I$201) -> 0 | F17: =SUMIF('14'!$M$2:$M$201,"Limit Exceeded",'14'!$I$2:$I$201) -> 0 | G17: =COUNTIF('14'!$M$2:$M$201,"Valid Approval") -> 0 | H17: =COUNTIF('14'!$M$2:$M$201,"Limit Exceeded") -> 0 | I17: =COUNTA('14'!$D$2:$D$201) -> 0
A18: 15 | B18: =SUMIF('15'!$N$2:$N$201,"CASH",'15'!$I$2:$I$201) -> 0 | C18: =SUMIF('15'!$N$2:$N$201,"VOUCHER",'15'!$I$2:$I$201) -> 0 | D18: =SUM('15'!$I$2:$I$201) -> 0 | E18: =SUMIF('15'!$M$2:$M$201,"Valid Approval",'15'!$I$2:$I$201) -> 0 | F18: =SUMIF('15'!$M$2:$M$201,"Limit Exceeded",'15'!$I$2:$I$201) -> 0 | G18: =COUNTIF('15'!$M$2:$M$201,"Valid Approval") -> 0 | H18: =COUNTIF('15'!$M$2:$M$201,"Limit Exceeded") -> 0 | I18: =COUNTA('15'!$D$2:$D$201) -> 0
A19: 16 | B19: =SUMIF('16'!$N$2:$N$201,"CASH",'16'!$I$2:$I$201) -> 0 | C19: =SUMIF('16'!$N$2:$N$201,"VOUCHER",'16'!$I$2:$I$201) -> 0 | D19: =SUM('16'!$I$2:$I$201) -> 0 | E19: =SUMIF('16'!$M$2:$M$201,"Valid Approval",'16'!$I$2:$I$201) -> 0 | F19: =SUMIF('16'!$M$2:$M$201,"Limit Exceeded",'16'!$I$2:$I$201) -> 0 | G19: =COUNTIF('16'!$M$2:$M$201,"Valid Approval") -> 0 | H19: =COUNTIF('16'!$M$2:$M$201,"Limit Exceeded") -> 0 | I19: =COUNTA('16'!$D$2:$D$201) -> 0
A20: 17 | B20: =SUMIF('17'!$N$2:$N$201,"CASH",'17'!$I$2:$I$201) -> 0 | C20: =SUMIF('17'!$N$2:$N$201,"VOUCHER",'17'!$I$2:$I$201) -> 0 | D20: =SUM('17'!$I$2:$I$201) -> 0 | E20: =SUMIF('17'!$M$2:$M$201,"Valid Approval",'17'!$I$2:$I$201) -> 0 | F20: =SUMIF('17'!$M$2:$M$201,"Limit Exceeded",'17'!$I$2:$I$201) -> 0 | G20: =COUNTIF('17'!$M$2:$M$201,"Valid Approval") -> 0 | H20: =COUNTIF('17'!$M$2:$M$201,"Limit Exceeded") -> 0 | I20: =COUNTA('17'!$D$2:$D$201) -> 0
A21: 18 | B21: =SUMIF('18'!$N$2:$N$201,"CASH",'18'!$I$2:$I$201) -> 0 | C21: =SUMIF('18'!$N$2:$N$201,"VOUCHER",'18'!$I$2:$I$201) -> 0 | D21: =SUM('18'!$I$2:$I$201) -> 0 | E21: =SUMIF('18'!$M$2:$M$201,"Valid Approval",'18'!$I$2:$I$201) -> 0 | F21: =SUMIF('18'!$M$2:$M$201,"Limit Exceeded",'18'!$I$2:$I$201) -> 0 | G21: =COUNTIF('18'!$M$2:$M$201,"Valid Approval") -> 0 | H21: =COUNTIF('18'!$M$2:$M$201,"Limit Exceeded") -> 0 | I21: =COUNTA('18'!$D$2:$D$201) -> 0
A22: 19 | B22: =SUMIF('19'!$N$2:$N$201,"CASH",'19'!$I$2:$I$201) -> 0 | C22: =SUMIF('19'!$N$2:$N$201,"VOUCHER",'19'!$I$2:$I$201) -> 0 | D22: =SUM('19'!$I$2:$I$201) -> 0 | E22: =SUMIF('19'!$M$2:$M$201,"Valid Approval",'19'!$I$2:$I$201) -> 0 | F22: =SUMIF('19'!$M$2:$M$201,"Limit Exceeded",'19'!$I$2:$I$201) -> 0 | G22: =COUNTIF('19'!$M$2:$M$201,"Valid Approval") -> 0 | H22: =COUNTIF('19'!$M$2:$M$201,"Limit Exceeded") -> 0 | I22: =COUNTA('19'!$D$2:$D$201) -> 0
A23: 20 | B23: =SUMIF('20'!$N$2:$N$201,"CASH",'20'!$I$2:$I$201) -> 0 | C23: =SUMIF('20'!$N$2:$N$201,"VOUCHER",'20'!$I$2:$I$201) -> 0 | D23: =SUM('20'!$I$2:$I$201) -> 0 | E23: =SUMIF('20'!$M$2:$M$201,"Valid Approval",'20'!$I$2:$I$201) -> 0 | F23: =SUMIF('20'!$M$2:$M$201,"Limit Exceeded",'20'!$I$2:$I$201) -> 0 | G23: =COUNTIF('20'!$M$2:$M$201,"Valid Approval") -> 0 | H23: =COUNTIF('20'!$M$2:$M$201,"Limit Exceeded") -> 0 | I23: =COUNTA('20'!$D$2:$D$201) -> 0
A24: 21 | B24: =SUMIF('21'!$N$2:$N$201,"CASH",'21'!$I$2:$I$201) -> 0 | C24: =SUMIF('21'!$N$2:$N$201,"VOUCHER",'21'!$I$2:$I$201) -> 0 | D24: =SUM('21'!$I$2:$I$201) -> 0 | E24: =SUMIF('21'!$M$2:$M$201,"Valid Approval",'21'!$I$2:$I$201) -> 0 | F24: =SUMIF('21'!$M$2:$M$201,"Limit Exceeded",'21'!$I$2:$I$201) -> 0 | G24: =COUNTIF('21'!$M$2:$M$201,"Valid Approval") -> 0 | H24: =COUNTIF('21'!$M$2:$M$201,"Limit Exceeded") -> 0 | I24: =COUNTA('21'!$D$2:$D$201) -> 0
A25: 22 | B25: =SUMIF('22'!$N$2:$N$201,"CASH",'22'!$I$2:$I$201) -> 0 | C25: =SUMIF('22'!$N$2:$N$201,"VOUCHER",'22'!$I$2:$I$201) -> 0 | D25: =SUM('22'!$I$2:$I$201) -> 0 | E25: =SUMIF('22'!$M$2:$M$201,"Valid Approval",'22'!$I$2:$I$201) -> 0 | F25: =SUMIF('22'!$M$2:$M$201,"Limit Exceeded",'22'!$I$2:$I$201) -> 0 | G25: =COUNTIF('22'!$M$2:$M$201,"Valid Approval") -> 0 | H25: =COUNTIF('22'!$M$2:$M$201,"Limit Exceeded") -> 0 | I25: =COUNTA('22'!$D$2:$D$201) -> 0
A26: 23 | B26: =SUMIF('23'!$N$2:$N$201,"CASH",'23'!$I$2:$I$201) -> 0 | C26: =SUMIF('23'!$N$2:$N$201,"VOUCHER",'23'!$I$2:$I$201) -> 0 | D26: =SUM('23'!$I$2:$I$201) -> 0 | E26: =SUMIF('23'!$M$2:$M$201,"Valid Approval",'23'!$I$2:$I$201) -> 0 | F26: =SUMIF('23'!$M$2:$M$201,"Limit Exceeded",'23'!$I$2:$I$201) -> 0 | G26: =COUNTIF('23'!$M$2:$M$201,"Valid Approval") -> 0 | H26: =COUNTIF('23'!$M$2:$M$201,"Limit Exceeded") -> 0 | I26: =COUNTA('23'!$D$2:$D$201) -> 0
A27: 24 | B27: =SUMIF('24'!$N$2:$N$201,"CASH",'24'!$I$2:$I$201) -> 0 | C27: =SUMIF('24'!$N$2:$N$201,"VOUCHER",'24'!$I$2:$I$201) -> 0 | D27: =SUM('24'!$I$2:$I$201) -> 0 | E27: =SUMIF('24'!$M$2:$M$201,"Valid Approval",'24'!$I$2:$I$201) -> 0 | F27: =SUMIF('24'!$M$2:$M$201,"Limit Exceeded",'24'!$I$2:$I$201) -> 0 | G27: =COUNTIF('24'!$M$2:$M$201,"Valid Approval") -> 0 | H27: =COUNTIF('24'!$M$2:$M$201,"Limit Exceeded") -> 0 | I27: =COUNTA('24'!$D$2:$D$201) -> 0
A28: 25 | B28: =SUMIF('25'!$N$2:$N$201,"CASH",'25'!$I$2:$I$201) -> 0 | C28: =SUMIF('25'!$N$2:$N$201,"VOUCHER",'25'!$I$2:$I$201) -> 0 | D28: =SUM('25'!$I$2:$I$201) -> 0 | E28: =SUMIF('25'!$M$2:$M$201,"Valid Approval",'25'!$I$2:$I$201) -> 0 | F28: =SUMIF('25'!$M$2:$M$201,"Limit Exceeded",'25'!$I$2:$I$201) -> 0 | G28: =COUNTIF('25'!$M$2:$M$201,"Valid Approval") -> 0 | H28: =COUNTIF('25'!$M$2:$M$201,"Limit Exceeded") -> 0 | I28: =COUNTA('25'!$D$2:$D$201) -> 0
A29: 26 | B29: =SUMIF('26'!$N$2:$N$201,"CASH",'26'!$I$2:$I$201) -> 0 | C29: =SUMIF('26'!$N$2:$N$201,"VOUCHER",'26'!$I$2:$I$201) -> 0 | D29: =SUM('26'!$I$2:$I$201) -> 0 | E29: =SUMIF('26'!$M$2:$M$201,"Valid Approval",'26'!$I$2:$I$201) -> 0 | F29: =SUMIF('26'!$M$2:$M$201,"Limit Exceeded",'26'!$I$2:$I$201) -> 0 | G29: =COUNTIF('26'!$M$2:$M$201,"Valid Approval") -> 0 | H29: =COUNTIF('26'!$M$2:$M$201,"Limit Exceeded") -> 0 | I29: =COUNTA('26'!$D$2:$D$201) -> 0
A30: 27 | B30: =SUMIF('27'!$N$2:$N$201,"CASH",'27'!$I$2:$I$201) -> 0 | C30: =SUMIF('27'!$N$2:$N$201,"VOUCHER",'27'!$I$2:$I$201) -> 0 | D30: =SUM('27'!$I$2:$I$201) -> 0 | E30: =SUMIF('27'!$M$2:$M$201,"Valid Approval",'27'!$I$2:$I$201) -> 0 | F30: =SUMIF('27'!$M$2:$M$201,"Limit Exceeded",'27'!$I$2:$I$201) -> 0 | G30: =COUNTIF('27'!$M$2:$M$201,"Valid Approval") -> 0 | H30: =COUNTIF('27'!$M$2:$M$201,"Limit Exceeded") -> 0 | I30: =COUNTA('27'!$D$2:$D$201) -> 0
A31: 28 | B31: =SUMIF('28'!$N$2:$N$201,"CASH",'28'!$I$2:$I$201) -> 0 | C31: =SUMIF('28'!$N$2:$N$201,"VOUCHER",'28'!$I$2:$I$201) -> 0 | D31: =SUM('28'!$I$2:$I$201) -> 0 | E31: =SUMIF('28'!$M$2:$M$201,"Valid Approval",'28'!$I$2:$I$201) -> 0 | F31: =SUMIF('28'!$M$2:$M$201,"Limit Exceeded",'28'!$I$2:$I$201) -> 0 | G31: =COUNTIF('28'!$M$2:$M$201,"Valid Approval") -> 0 | H31: =COUNTIF('28'!$M$2:$M$201,"Limit Exceeded") -> 0 | I31: =COUNTA('28'!$D$2:$D$201) -> 0
A32: 29 | B32: =SUMIF('29'!$N$2:$N$201,"CASH",'29'!$I$2:$I$201) -> 0 | C32: =SUMIF('29'!$N$2:$N$201,"VOUCHER",'29'!$I$2:$I$201) -> 0 | D32: =SUM('29'!$I$2:$I$201) -> 0 | E32: =SUMIF('29'!$M$2:$M$201,"Valid Approval",'29'!$I$2:$I$201) -> 0 | F32: =SUMIF('29'!$M$2:$M$201,"Limit Exceeded",'29'!$I$2:$I$201) -> 0 | G32: =COUNTIF('29'!$M$2:$M$201,"Valid Approval") -> 0 | H32: =COUNTIF('29'!$M$2:$M$201,"Limit Exceeded") -> 0 | I32: =COUNTA('29'!$D$2:$D$201) -> 0
A33: 30 | B33: =SUMIF('30'!$N$2:$N$201,"CASH",'30'!$I$2:$I$201) -> 0 | C33: =SUMIF('30'!$N$2:$N$201,"VOUCHER",'30'!$I$2:$I$201) -> 0 | D33: =SUM('30'!$I$2:$I$201) -> 0 | E33: =SUMIF('30'!$M$2:$M$201,"Valid Approval",'30'!$I$2:$I$201) -> 0 | F33: =SUMIF('30'!$M$2:$M$201,"Limit Exceeded",'30'!$I$2:$I$201) -> 0 | G33: =COUNTIF('30'!$M$2:$M$201,"Valid Approval") -> 0 | H33: =COUNTIF('30'!$M$2:$M$201,"Limit Exceeded") -> 0 | I33: =COUNTA('30'!$D$2:$D$201) -> 0
A34: 31 | B34: =SUMIF('31'!$N$2:$N$201,"CASH",'31'!$I$2:$I$201) -> 0 | C34: =SUMIF('31'!$N$2:$N$201,"VOUCHER",'31'!$I$2:$I$201) -> 0 | D34: =SUM('31'!$I$2:$I$201) -> 0 | E34: =SUMIF('31'!$M$2:$M$201,"Valid Approval",'31'!$I$2:$I$201) -> 0 | F34: =SUMIF('31'!$M$2:$M$201,"Limit Exceeded",'31'!$I$2:$I$201) -> 0 | G34: =COUNTIF('31'!$M$2:$M$201,"Valid Approval") -> 0 | H34: =COUNTIF('31'!$M$2:$M$201,"Limit Exceeded") -> 0 | I34: =COUNTA('31'!$D$2:$D$201) -> 0
A35: Grand Total | B35: =SUM(B4:B34) -> 0 | C35: =SUM(C4:C34) -> 0 | D35: =SUM(D4:D34) -> 0 | E35: =SUM(E4:E34) -> 0 | F35: =SUM(F4:F34) -> 0 | G35: =SUM(G4:G34) -> 0 | H35: =SUM(H4:H34) -> 0 | I35: =SUM(I4:I34) -> 0
A37: Duplicate Alert: Repeated Return Trx is highlighted RED and repeated Trx No is highlighted YELLOW across all day sheets.

Sheet Print Form
A1: RETURN APPROVAL FORM
A4: Day | B4: =Search!$B$3 -> 1 | E4: Approval Name | F4: =Search!$K$9 -> Not Found
A5: Customer Name | B5: =Search!$B$9 -> Not Found | E5: Designation | F5: =Search!$L$9 -> Not Found
A6: Contact No | B6: =Search!$C$9 -> Not Found | E6: System Status | F6: =Search!$M$9 -> Not Found
A7: Return Trx | B7: =Search!$D$9 -> Not Found | E7: Reason | F7: =Search!$J$9 -> Not Found
A8: Trx No | B8: =Search!$E$9 -> Not Found | E8: Item Exp Date | F8: =Search!$G$9 -> Not Found
A9: Item Description | B9: =Search!$F$9 -> Not Found | E9: Received By | F9: =Search!$O$9 -> Not Found
A10: Qty | B10: =Search!$H$9 -> Not Found | E10: CCTV/Time | F10: =Search!$P$9 -> Not Found
A11: Total Amount | B11: =Search!$I$9 -> Not Found | E11: Trx Time | F11: =Search!$Q$9 -> Not Found
A12: Cash/Voucher | B12: =Search!$N$9 -> Not Found | E12: Printed On | F12: =TODAY() -> 46237
A15: Authorized Signature: ____________________________

Sheet Management
A1: RETURN APPROVAL MANAGEMENT SETUP
A2: Designation | B2: Management Name (Edit Here) | C2: Approval Limit
A3: Section Executive | B3: Muhammad Usman | C3: 5000 | G3: J SO | H3: 500
A4: Senior Section Officer | B4: Nadeem Hussain | C4: 3000 | G4: SO | H4: 2000
A5: Jr. Section Officer | B5: Allah Ditta | C5: 500 | G5: SSO | H5: 3000
A6: Associate Floor Manager | B6: Mehmood Ahmed | C6: 9000 | G6: Executive | H6: 5000
A7: Jr. Section Officer | B7: Tasawar Abbas | C7: 500 | G7: Floor Manager | H7: 9000
A8: Senior Section Officer | B8: Muhammad Farhan | C8: 3000 | G8: Store Manager | H8: Unlimited
A9: Jr. Section Officer | B9: Shahzaib Ali | C9: 500
A10: Jr. Section Officer | B10: Waseem Raza | C10: 500
A11: Head Chef | B11: Muhammad Majeed | C11: 3000
A12: Section Officer | B12: Shoukat Mahmood | C12: 2000
A13: Section Executive | B13: Naveed Kamal | C13: 5000
A14: Section Officer | B14: Raza Ali | C14: 2000
A15: Head Chef | B15: Alfqar | C15: 3000
A16: Section Officer | B16: Sheraz Ahmed | C16: 2000
A17: Senior Section Officer | B17: Faisal Kausar | C17: 3000
A18: Senior Section Officer | B18: Muhammad Faisal | C18: 3000
A19: Jr. Section Officer | B19: Sumair Hamza | C19: 500
A20: Section Officer | B20: Muhammad Ali | C20: 2000
... A24: Section Officer | B24: Asad Mehmood | C24: 2000
A25: Manager - Store Operations | B25: Muhammad Salman | C25: Unlimited
A26: Associate Floor Manager | B26: Muzammil Hussain | C26: 9000
A27: Section Executive | B27: Muhammad Muneer | C27: 5000
A69: ADMIN / MANAGEMENT SETUP
A70: 1 | B70: Column B mein authorized management ke actual names sirf admin ek martaba enter kare.
A71: 2 | B71: Return Entry sheet mein Approval Name aur Designation amount ke mutabiq automatic aayenge.
A72: 3 | B72: Cash/Voucher column mein sirf CASH ya VOUCHER select hoga; baqi entry columns open hain.

Sheet 1
A1: S.No. | B1: Customer Name | C1: Contact No | D1: Return Trx | E1: Trx No | F1: Item Description | G1: Item Exp Date | H1: Qty | I1: Total Amount | J1: Reason | K1: Approval Name (Auto) | L1: Designation (Auto) | M1: System Status | N1: Cash/Voucher | O1: Rcv by | P1: CCTV/Time | Q1: Trx Time
A2: =IF(D2="","",ROW()-1) | L2: =IF(K2="","",IFERROR(INDEX(Management!$A$3:$A$50,MATCH(K2,Management!$B$3:$B$50,0)),"")) | M2: =IF(I2="","",IF(K2="","Select Approval Name",IFERROR(IF(I2<=IF(INDEX(Management!$C$3:$C$50,MATCH(K2,Management!$B$3:$B$50,0))="Unlimited",10^15,INDEX(Management!$C$3:$C$50,MATCH(K2,Management!$B$3:$B$50,0))),"Valid Approval","Limit Exceeded"),"Check Management Name")))
A3: =IF(D3="","",ROW()-1) | L3: =IF(K3="","",IFERROR(INDEX(Management!$A$3:$A$50,MATCH(K3,Management!$B$3:$B$50,0)),"")) | M3: =IF(I3="","",IF(K3="","Select Approval Name",IFERROR(IF(I3<=IF(INDEX(Management!$C$3:$C$50,MATCH(K3,Management!$B$3:$B$50,0))="Unlimited",10^15,INDEX(Management!$C$3:$C$50,MATCH(K3,Management!$B$3:$B$50,0))),"Valid Approval","Limit Exceeded"),"Check Management Name")))
A4: =IF(D4="","",ROW()-1) | L4: =IF(K4="","",IFERROR(INDEX(Management!$A$3:$A$50,MATCH(K4,Management!$B$3:$B$50,0)),"")) | M4: =IF(I4="","",IF(K4="","Select Approval Name",IFERROR(IF(I4<=IF(INDEX(Management!$C$3:$C$50,MATCH(K4,Management!$B$3:$B$50,0))="Unlimited",10^15,INDEX(Management!$C$3:$C$50,MATCH(K4,Management!$B$3:$B$50,0))),"Valid Approval","Limit Exceeded"),"Check Management Name")))
A5: =IF(D5="","",ROW()-1) | L5: =IF(K5="","",IFERROR(INDEX(Management!$A$3:$A$50,MATCH(K5,Management!$B$3:$B$50,0)),"")) | M5: =IF(I5="","",IF(K5="","Select Approval Name",IFERROR(IF(I5<=IF(INDEX(Management!$C$3:$C$50,MATCH(K5,Management!$B$3:$B$50,0))="Unlimited",10^15,INDEX(Management!$C$3:$C$50,MATCH(K5,Management!$B$3:$B$50,0))),"Valid Approval","Limit Exceeded"),"Check Management Name")))
A6: =IF(D6="","",ROW()-1) | L6: =IF(K6="","",IFERROR(INDEX(Management!$A$3:$A$50,MATCH(K6,Management!$B$3:$B$50,0)),"")) | M6: =IF(I6="","",IF(K6="","Select Approval Name",IFERROR(IF(I6<=IF(INDEX(Management!$C$3:$C$50,MATCH(K6,Management!$B$3:$B$50,0))="Unlimited",10^15,INDEX(Management!$C$3:$C$50,MATCH(K6,Management!$B$3:$B$50,0))),"Valid Approval","Limit Exceeded"),"Check Management Name")))
A7: =IF(D7="","",ROW()-1) | L7: =IF(K7="","",IFERROR(INDEX(Management!$A$3:$A$50,MATCH(K7,Management!$B$3:$B$50,0)),"")) | M7: =IF(I7="","",IF(K7="","Select Approval Name",IFERROR(IF(I7<=IF(INDEX(Management!$C$3:$C$50,MATCH(K7,Management!$B$3:$B$50,0))="Unlimited",10^15,INDEX(Management!$C$3:$C$50,MATCH(K7,Management!$B$3:$B$50,0))),"Valid Approval","Limit Exceeded"),"Check Management Name")))
A8: =IF(D8="","",ROW()-1) | L8: =IF(K8="","",IFERROR(INDEX(Management!$A$3:$A$50,MATCH(K8,Management!$B$3:$B$50,0)),"")) | M8: =IF(I8="","",IF(K8="","Select Approval Name",IFERROR(IF(I8<=IF(INDEX(Management!$C$3:$C$50,MATCH(K8,Management!$B$3:$B$50,0))="Unlimited",10^15,INDEX(Management!$C$3:$C$50,MATCH(K8,Management!$B$3:$B$50,0))),"Valid Approval","Limit Exceeded"),"Check Management Name")))
A9: =IF(D9="","",ROW()-1) | L9: =IF(K9="","",IFERROR(INDEX(Management!$A$3:$A$50,MATCH(K9,Management!$B$3:$B$50,0)),"")) | M9: =IF(I9="","",IF(K9="","Select Approval Name",IFERROR(IF(I9<=IF(INDEX(Management!$C$3:$C$50,MATCH(K9,Management!$B$3:$B$50,0))="Unlimited",10^15,INDEX(Management!$C$3:$C$50,MATCH(K9,Management!$B$3:$B$50,0))),"Valid Approval","Limit Exceeded"),"Check Management Name")))
A10: =IF(D10="","",ROW()-1) | L10: =IF(K10="","",IFERROR(INDEX(Management!$A$3:$A$50,MATCH(K10,Management!$B$3:$B$50,0)),"")) | M10: =IF(I10="","",IF(K10="","Select Approval Name",IFERROR(IF(I10<=IF(INDEX(Management!$C$3:$C$50,MATCH(K10,Management!$B$3:$B$50,0))="Unlimited",10^15,INDEX(Management!$C$3:$C$50,MATCH(K10,Management!$B$3:$B$50,0))),"Valid Approval","Limit Exceeded"),"Check Management Name")))
A11: =IF(D11="","",ROW()-1) | L11: =IF(K11="","",IFERROR(INDEX(Management!$A$3:$A$50,MATCH(K11,Management!$B$3:$B$50,0)),"")) | M11: =IF(I11="","",IF(K11="","Select Approval Name",IFERROR(IF(I11<=IF(INDEX(Management!$C$3:$C$50,MATCH(K11,Management!$B$3:$B$50,0))="Unlimited",10^15,INDEX(Management!$C$3:$C$50,MATCH(K11,Management!$B$3:$B$50,0))),"Valid Approval","Limit Exceeded"),"Check Management Name")))
A12: =IF(D12="","",ROW()-1) | L12: =IF(K12="","",IFERROR(INDEX(Management!$A$3:$A$50,MATCH(K12,Management!$B$3:$B$50,0)),"")) | M12: =IF(I12="","",IF(K12="","Select Approval Name",IFERROR(IF(I12<=IF(INDEX(Management!$C$3:$C$50,MATCH(K12,Management!$B$3:$B$50,0))="Unlimited",10^15,INDEX(Management!$C$3:$C$50,MATCH(K12,Management!$B$3:$B$50,0))),"Valid Approval","Limit Exceeded"),"Check Management Name")))
A13: =IF(D13="","",ROW()-1) | L13: =IF(K13="","",IFERROR(INDEX(Management!$A$3:$A$50,MATCH(K13,Management!$B$3:$B$50,0)),"")) | M13: =IF(I13="","",IF(K13="","Select Approval Name",IFERROR(IF(I13<=IF(INDEX(Management!$C$3:$C$50,MATCH(K13,Management!$B$3:$B$50,0))="Unlimited",10^15,INDEX(Management!$C$3:$C$50,MATCH(K13,Management!$B$3:$B$50,0))),"Valid Approval","Limit Exceeded"),"Check Management Name")))
... A201: =IF(D201="","",ROW()-1) | L201: =IF(K201="","",IFERROR(INDEX(Management!$A$3:$A$50,MATCH(K201,Management!$B$3:$B$50,0)),"")) | M201: =IF(I201="","",IF(K201="","Select Approval Name",IFERROR(IF(I201<=IF(INDEX(Management!$C$3:$C$50,MATCH(K201,Management!$B$3:$B$50,0))="Unlimited",10^15,INDEX(Management!$C$3:$C$50,MATCH(K201,Management!$B$3:$B$50,0))),"Valid Approval","Limit Exceeded"),"Check Management Name")))

Sheet 2
A1: S.No. | B1: Customer Name | C1: Contact No | D1: Return Trx | E1: Trx No | F1: Item Description | G1: Item Exp Date | H1: Qty | I1: Total Amount | J1: Reason | K1: Approval Name (Auto) | L1: Designation (Auto) | M1: System Status | N1: Cash/Voucher | O1: Rcv by | P1: CCTV/Time | Q1: Trx Time
A2: =IF(D2="","",ROW()-1) | L2: =IF(K2="","",IFERROR(INDEX(Management!$A$3:$A$50,MATCH(K2,Management!$B$3:$B$50,0)),"")) | M2: =IF(I2="","",IF(K2="","Select Approval Name",IFERROR(IF(I2<=IF(INDEX(Management!$C$3:$C$50,MATCH(K2,Management!$B$3:$B$50,0))="Unlimited",10^15,INDEX(Management!$C$3:$C$50,MATCH(K2,Management!$B$3:$B$50,0))),"Valid Approval","Limit Exceeded"),"Check Management Name")))
A3: =IF(D3="","",ROW()-1) | L3: =IF(K3="","",IFERROR(INDEX(Management!$A$3:$A$50,MATCH(K3,Management!$B$3:$B$50,0)),"")) | M3: =IF(I3="","",IF(K3="","Select Approval Name",IFERROR(IF(I3<=IF(INDEX(Management!$C$3:$C$50,MATCH(K3,Management!$B$3:$B$50,0))="Unlimited",10^15,INDEX(Management!$C$3:$C$50,MATCH(K3,Management!$B$3:$B$50,0))),"Valid Approval","Limit Exceeded"),"Check Management Name")))
A4: =IF(D4="","",ROW()-1) | L4: =IF(K4="","",IFERROR(INDEX(Management!$A$3:$A$50,MATCH(K4,Management!$B$3:$B$50,0)),"")) | M4: =IF(I4="","",IF(K4="","Select Approval Name",IFERROR(IF(I4<=IF(INDEX(Management!$C$3:$C$50,MATCH(K4,Management!$B$3:$B$50,0))="Unlimited",10^15,INDEX(Management!$C$3:$C$50,MATCH(K4,Management!$B$3:$B$50,0))),"Valid Approval","Limit Exceeded"),"Check Management Name")))
A5: =IF(D5="","",ROW()-1) | L5: =IF(K5="","",IFERROR(INDEX(Management!$A$3:$A$50,MATCH(K5,Management!$B$3:$B$50,0)),"")) | M5: =IF(I5="","",IF(K5="","Select Approval Name",IFERROR(IF(I5<=IF(INDEX(Management!$C$3:$C$50,MATCH(K5,Management!$B$3:$B$50,0))="Unlimited",10^15,INDEX(Management!$C$3:$C$50,MATCH(K5,Management!$B$3:$B$50,0))),"Valid Approval","Limit Exceeded"),"Check Management Name")))
A6: =IF(D6="","",ROW()-1) | L6: =IF(K6="","",IFERROR(INDEX(Management!$A$3:$A$50,MATCH(K6,Management!$B$3:$B$50,0)),"")) | M6: =IF(I6="","",IF(K6="","Select Approval Name",IFERROR(IF(I6<=IF(INDEX(Management!$C$3:$C$50,MATCH(K6,Management!$B$3:$B$50,0))="Unlimited",10^15,INDEX(Management!$C$3:$C$50,MATCH(K6,Management!$B$3:$B$50,0))),"Valid Approval","Limit Exceeded"),"Check Management Name")))
A7: =IF(D7="","",ROW()-1) | L7: =IF(K7="","",IFERROR(INDEX(Management!$A$3:$A$50,MATCH(K7,Management!$B$3:$B$50,0)),"")) | M7: =IF(I7="","",IF(K7="","Select Approval Name",IFERROR(IF(I7<=IF(INDEX(Management!$C$3:$C$50,MATCH(K7,Management!$B$3:$B$50,0))="Unlimited",10^15,INDEX(Management!$C$3:$C$50,MATCH(K7,Management!$B$3:$B$50,0))),"Valid Approval","Limit Exceeded"),"Check Management Name")))
A8: =IF(D8="","",ROW()-1) | L8: =IF(K8="","",IFERROR(INDEX(Management!$A$3:$A$50,MATCH(K8,Management!$B$3:$B$50,0)),"")) | M8: =IF(I8="","",IF(K8="","Select Approval Name",IFERROR(IF(I8<=IF(INDEX(Management!$C$3:$C$50,MATCH(K8,Management!$B$3:$B$50,0))="Unlimited",10^15,INDEX(Management!$C$3:$C$50,MATCH(K8,Management!$B$3:$B$50,0))),"Valid Approval","Limit Exceeded"),"Check Management Name")))
A9: =IF(D9="","",ROW()-1) | L9: =IF(K9="","",IFERROR(INDEX(Management!$A$3:$A$50,MATCH(K9,Management!$B$3:$B$50,0)),"")) | M9: =IF(I9="","",IF(K9="","Select Approval Name",IFERROR(IF(I9<=IF(INDEX(Management!$C$3:$C$50,MATCH(K9,Management!$B$3:$B$50,0))="Unlimited",10^15,INDEX(Management!$C$3:$C$50,MATCH(K9,Management!$B$3:$B$50,0))),"Valid Approval","Limit Exceeded"),"Check Management Name")))
A10: =IF(D10="","",ROW()-1) | L10: =IF(K10="","",IFERROR(INDEX(Management!$A$3:$A$50,MATCH(K10,Management!$B$3:$B$50,0)),"")) | M10: =IF(I10="","",IF(K10="","Select Approval Name",IFERROR(IF(I10<=IF(INDEX(Management!$C$3:$C$50,MATCH(K10,Management!$B$3:$B$50,0))="Unlimited",10^15,INDEX(Management!$C$3:$C$50,MATCH(K10,Management!$B$3:$B$50,0))),"Valid Approval","Limit Exceeded"),"Check Management Name")))
A11: =IF(D11="","",ROW()-1) | L11: =IF(K11="","",IFERROR(INDEX(Management!$A$3:$A$50,MATCH(K11,Management!$B$3:$B$50,0)),"")) | M11: =IF(I11="","",IF(K11="","Select Approval Name",IFERROR(IF(I11<=IF(INDEX(Management!$C$3:$C$50,MATCH(K11,Management!$B$3:$B$50,0))="Unlimited",10^15,INDEX(Management!$C$3:$C$50,MATCH(K11,Management!$B$3:$B$50,0))),"Valid Approval","Limit Exceeded"),"Check Management Name")))
A12: =IF(D12="","",ROW()-1) | L12: =IF(K12="","",IFERROR(INDEX(Management!$A$3:$A$50,MATCH(K12,Management!$B$3:$B$50,0)),"")) | M12: =IF(I12="","",IF(K12="","Select Approval Name",IFERROR(IF(I12<=IF(INDEX(Management!$C$3:$C$50,MATCH(K12,Management!$B$3:$B$50,0))="Unlimited",10^15,INDEX(Management!$C$3:$C$50,MATCH(K12,Management!$B$3:$B$50,0))),"Valid Approval","Limit Exceeded"),"Check Management Name")))
A13: =IF(D13="","",ROW()-1) | L13: =IF(K13="","",IFERROR(INDEX(Management!$A$3:$A$50,MATCH(K13,Management!$B$3:$B$50,0)),"")) | M13: =IF(I13="","",IF(K13="","Select Approval Name",IFERROR(IF(I13<=IF(INDEX(Management!$C$3:$C$50,MATCH(K13,Management!$B$3:$B$50,0))="Unlimited",10^15,INDEX(Management!$C$3:$C$50,MATCH(K13,Management!$B$3:$B$50,0))),"Valid Approval","Limit Exceeded"),"Check Management Name")))
... A201: =IF(D201="","",ROW()-1) | L201: =IF(K201="","",IFERROR(INDEX(Management!$A$3:$A$50,MATCH(K201,Management!$B$3:$B$50,0)),"")) | M201: =IF(I201="","",IF(K201="","Select Approval Name",IFERROR(IF(I201<=IF(INDEX(Management!$C$3:$C$50,MATCH(K201,Management!$B$3:$B$50,0))="Unlimited",10^15,INDEX(Management!$C$3:$C$50,MATCH(K201,Management!$B$3:$B$50,0))),"Valid Approval","Limit Exceeded"),"Check Management Name")))

Sheet 3
A1: S.No. | B1: Customer Name | C1: Contact No | D1: Return Trx | E1: Trx No | F1: Item Description | G1: Item Exp Date | H1: Qty | I1: Total Amount | J1: Reason | K1: Approval Name (Auto) | L1: Designation (Auto) | M1: System Status | N1: Cash/Voucher | O1: Rcv by | P1: CCTV/Time | Q1: Trx Time
A2: =IF(D2="","",ROW()-1) | L2: =IF(K2="","",IFERROR(INDEX(Management!$A$3:$A$50,MATCH(K2,Management!$B$3:$B$50,0)),"")) | M2: =IF(I2="","",IF(K2="","Select Approval Name",IFERROR(IF(I2<=IF(INDEX(Management!$C$3:$C$50,MATCH(K2,Management!$B$3:$B$50,0))="Unlimited",10^15,INDEX(Management!$C$3:$C$50,MATCH(K2,Management!$B$3:$B$50,0))),"Valid Approval","Limit Exceeded"),"Check Management Name")))
A3: =IF(D3="","",ROW()-1) | L3: =IF(K3="","",IFERROR(INDEX(Management!$A$3:$A$50,MATCH(K3,Management!$B$3:$B$50,0)),"")) | M3: =IF(I3="","",IF(K3="","Select Approval Name",IFERROR(IF(I3<=IF(INDEX(Management!$C$3:$C$50,MATCH(K3,Management!$B$3:$B$50,0))="Unlimited",10^15,INDEX(Management!$C$3:$C$50,MATCH(K3,Management!$B$3:$B$50,0))),"Valid Approval","Limit Exceeded"),"Check Management Name")))
A4: =IF(D4="","",ROW()-1) | L4: =IF(K4="","",IFERROR(INDEX(Management!$A$3:$A$50,MATCH(K4,Management!$B$3:$B$50,0)),"")) | M4: =IF(I4="","",IF(K4="","Select Approval Name",IFERROR(IF(I4<=IF(INDEX(Management!$C$3:$C$50,MATCH(K4,Management!$B$3:$B$50,0))="Unlimited",10^15,INDEX(Management!$C$3:$C$50,MATCH(K4,Management!$B$3:$B$50,0))),"Valid Approval","Limit Exceeded"),"Check Management Name")))
A5: =IF(D5="","",ROW()-1) | L5: =IF(K5="","",IFERROR(INDEX(Management!$A$3:$A$50,MATCH(K5,Management!$B$3:$B$50,0)),"")) | M5: =IF(I5="","",IF(K5="","Select Approval Name",IFERROR(IF(I5<=IF(INDEX(Management!$C$3:$C$50,MATCH(K5,Management!$B$3:$B$50,0))="Unlimited",10^15,INDEX(Management!$C$3:$C$50,MATCH(K5,Management!$B$3:$B$50,0))),"Valid Approval","Limit Exceeded"),"Check Management Name")))
A6: =IF(D6="","",ROW()-1) | L6: =IF(K6="","",IFERROR(INDEX(Management!$A$3:$A$50,MATCH(K6,Management!$B$3:$B$50,0)),"")) | M6: =IF(I6="","",IF(K6="","Select Approval Name",IFERROR(IF(I6<=IF(INDEX(Management!$C$3:$C$50,MATCH(K6,Management!$B$3:$B$50,0))="Unlimited",10^15,INDEX(Management!$C$3:$C$50,MATCH(K6,Management!$B$3:$B$50,0))),"Valid Approval","Limit Exceeded"),"Check Management Name")))
A7: =IF(D7="","",ROW()-1) | L7: =IF(K7="","",IFERROR(INDEX(Management!$A$3:$A$50,MATCH(K7,Management!$B$3:$B$50,0)),"")) | M7: =IF(I7="","",IF(K7="","Select Approval Name",IFERROR(IF(I7<=IF(INDEX(Management!$C$3:$C$50,MATCH(K7,Management!$B$3:$B$50,0))="Unlimited",10^15,INDEX(Management!$C$3:$C$50,MATCH(K7,Management!$B$3:$B$50,0))),"Valid Approval","Limit Exceeded"),"Check Management Name")))
A8: =IF(D8="","",ROW()-1) | L8: =IF(K8="","",IFERROR(INDEX(Management!$A$3:$A$50,MATCH(K8,Management!$B$3:$B$50,0)),"")) | M8: =IF(I8="","",IF(K8="","Select Approval Name",IFERROR(IF(I8<=IF(INDEX(Management!$C$3:$C$50,MATCH(K8,Management!$B$3:$B$50,0))="Unlimited",10^15,INDEX(Management!$C$3:$C$50,MATCH(K8,Management!$B$3:$B$50,0))),"Valid Approval","Limit Exceeded"),"Check Management Name")))
A9: =IF(D9="","",ROW()-1) | L9: =IF(K9="","",IFERROR(INDEX(Management!$A$3:$A$50,MATCH(K9,Management!$B$3:$B$50,0)),"")) | M9: =IF(I9="","",IF(K9="","Select Approval Name",IFERROR(IF(I9<=IF(INDEX(Management!$C$3:$C$50,MATCH(K9,Management!$B$3:$B$50,0))="Unlimited",10^15,INDEX(Management!$C$3:$C$50,MATCH(K9,Management!$B$3:$B$50,0))),"Valid Approval","Limit Exceeded"),"Check Management Name")))
A10: =IF(D10="","",ROW()-1) | L10: =IF(K10="","",IFERROR(INDEX(Management!$A$3:$A$50,MATCH(K10,Management!$B$3:$B$50,0)),"")) | M10: =IF(I10="","",IF(K10="","Select Approval Name",IFERROR(IF(I10<=IF(INDEX(Management!$C$3:$C$50,MATCH(K10,Management!$B$3:$B$50,0))="Unlimited",10^15,INDEX(Management!$C$3:$C$50,MATCH(K10,Management!$B$3:$B$50,0))),"Valid Approval","Limit Exceeded"),"Check Management Name")))
A11: =IF(D11="","",ROW()-1) | L11: =IF(K11="","",IFERROR(INDEX(Management!$A$3:$A$50,MATCH(K11,Management!$B$3:$B$50,0)),"")) | M11: =IF(I11="","",IF(K11="","Select Approval Name",IFERROR(IF(I11<=IF(INDEX(Management!$C$3:$C$50,MATCH(K11,Management!$B$3:$B$50,0))="Unlimited",10^15,INDEX(Management!$C$3:$C$50,MATCH(K11,Management!$B$3:$B$50,0))),"Valid Approval","Limit Exceeded"),"Check Management Name")))
A12: =IF(D12="","",ROW()-1) | L12: =IF(K12="","",IFERROR(INDEX(Management!$A$3:$A$50,MATCH(K12,Management!$B$3:$B$50,0)),"")) | M12: =IF(I12="","",IF(K12="","Select Approval Name",IFERROR(IF(I12<=IF(INDEX(Management!$C$3:$C$50,MATCH(K12,Management!$B$3:$B$50,0))="Unlimited",10^15,INDEX(Management!$C$3:$C$50,MATCH(K12,Management!$B$3:$B$50,0))),"Valid Approval","Limit Exceeded"),"Check Management Name")))
A13: =IF(D13="","",ROW()-1) | L13: =IF(K13="","",IFERROR(INDEX(Management!$A$3:$A$50,MATCH(K13,Management!$B$3:$B$50,0)),"")) | M13: =IF(I13="","",IF(K13="","Select Approval Name",IFERROR(IF(I13<=IF(INDEX(Management!$C$3:$C$50,MATCH(K13,Management!$B$3:$B$50,0))="Unlimited",10^15,INDEX(Management!$C$3:$C$50,MATCH(K13,Management!$B$3:$B$50,0))),"Valid Approval","Limit Exceeded"),"Check Management Name")))
... A201: =IF(D201="","",ROW()-1) | L201: =IF(K201="","",IFERROR(INDEX(Management!$A$3:$A$50,MATCH(K201,Management!$B$3:$B$50,0)),"")) | M201: =IF(I201="","",IF(K201="","Select Approval Name",IFERROR(IF(I201<=IF(INDEX(Management!$C$3:$C$50,MATCH(K201,Management!$B$3:$B$50,0))="Unlimited",10^15,INDEX(Management!$C$3:$C$50,MATCH(K201,Management!$B$3:$B$50,0))),"Valid Approval","Limit Exceeded"),"Check Management Name")))

Sheet 4
A1: S.No. | B1: Customer Name | C1: Contact No | D1: Return Trx | E1: Trx No | F1: Item Description | G1: Item Exp Date | H1: Qty | I1: Total Amount | J1: Reason | K1: Approval Name (Auto) | L1: Designation (Auto) | M1: System Status | N1: Cash/Voucher | O1: Rcv by | P1: CCTV/Time | Q1: Trx Time
A2: =IF(D2="","",ROW()-1) | L2: =IF(K2="","",IFERROR(INDEX(Management!$A$3:$A$50,MATCH(K2,Management!$B$3:$B$50,0)),"")) | M2: =IF(I2="","",IF(K2="","Select Approval Name",IFERROR(IF(I2<=IF(INDEX(Management!$C$3:$C$50,MATCH(K2,Management!$B$3:$B$50,0))="Unlimited",10^15,INDEX(Management!$C$3:$C$50,MATCH(K2,Management!$B$3:$B$50,0))),"Valid Approval","Limit Exceeded"),"Check Management Name")))
A3: =IF(D3="","",ROW()-1) | L3: =IF(K3="","",IFERROR(INDEX(Management!$A$3:$A$50,MATCH(K3,Management!$B$3:$B$50,0)),"")) | M3: =IF(I3="","",IF(K3="","Select Approval Name",IFERROR(IF(I3<=IF(INDEX(Management!$C$3:$C$50,MATCH(K3,Management!$B$3:$B$50,0))="Unlimited",10^15,INDEX(Management!$C$3:$C$50,MATCH(K3,Management!$B$3:$B$50,0))),"Valid Approval","Limit Exceeded"),"Check Management Name")))
A4: =IF(D4="","",ROW()-1) | L4: =IF(K4="","",IFERROR(INDEX(Management!$A$3:$A$50,MATCH(K4,Management!$B$3:$B$50,0)),"")) | M4: =IF(I4="","",IF(K4="","Select Approval Name",IFERROR(IF(I4<=IF(INDEX(Management!$C$3:$C$50,MATCH(K4,Management!$B$3:$B$50,0))="Unlimited",10^15,INDEX(Management!$C$3:$C$50,MATCH(K4,Management!$B$3:$B$50,0))),"Valid Approval","Limit Exceeded"),"Check Management Name")))
A5: =IF(D5="","",ROW()-1) | L5: =IF(K5="","",IFERROR(INDEX(Management!$A$3:$A$50,MATCH(K5,Management!$B$3:$B$50,0)),"")) | M5: =IF(I5="","",IF(K5="","Select Approval Name",IFERROR(IF(I5<=IF(INDEX(Management!$C$3:$C$50,MATCH(K5,Management!$B$3:$B$50,0))="Unlimited",10^15,INDEX(Management!$C$3:$C$50,MATCH(K5,Management!$B$3:$B$50,0))),"Valid Approval","Limit Exceeded"),"Check Management Name")))
A6: =IF(D6="","",ROW()-1) | L6: =IF(K6="","",IFERROR(INDEX(Management!$A$3:$A$50,MATCH(K6,Management!$B$3:$B$50,0)),"")) | M6: =IF(I6="","",IF(K6="","Select Approval Name",IFERROR(IF(I6<=IF(INDEX(Management!$C$3:$C$50,MATCH(K6,Management!$B$3:$B$50,0))="Unlimited",10^15,INDEX(Management!$C$3:$C$50,MATCH(K6,Management!$B$3:$B$50,0))),"Valid Approval","Limit Exceeded"),"Check Management Name")))
A7: =IF(D7="","",ROW()-1) | L7: =IF(K7="","",IFERROR(INDEX(Management!$A$3:$A$50,MATCH(K7,Management!$B$3:$B$50,0)),"")) | M7: =IF(I7="","",IF(K7="","Select Approval Name",IFERROR(IF(I7<=IF(INDEX(Management!$C$3:$C$50,MATCH(K7,Management!$B$3:$B$50,0))="Unlimited",10^15,INDEX(Management!$C$3:$C$50,MATCH(K7,Management!$B$3:$B$50,0))),"Valid Approval","Limit Exceeded"),"Check Management Name")))
A8: =IF(D8="","",ROW()-1) | L8: =IF(K8="","",IFERROR(INDEX(Management!$A$3:$A$50,MATCH(K8,Management!$B$3:$B$50,0)),"")) | M8: =IF(I8="","",IF(K8="","Select Approval Name",IFERROR(IF(I8<=IF(INDEX(Management!$C$3:$C$50,MATCH(K8,Management!$B$3:$B$50,0))="Unlimited",10^15,INDEX(Management!$C$3:$C$50,MATCH(K8,Management!$B$3:$B$50,0))),"Valid Approval","Limit Exceeded"),"Check Management Name")))
A9: =IF(D9="","",ROW()-1) | L9: =IF(K9="","",IFERROR(INDEX(Management!$A$3:$A$50,MATCH(K9,Management!$B$3:$B$50,0)),"")) | M9: =IF(I9="","",IF(K9="","Select Approval Name",IFERROR(IF(I9<=IF(INDEX(Management!$C$3:$C$50,MATCH(K9,Management!$B$3:$B$50,0))="Unlimited",10^15,INDEX(Management!$C$3:$C$50,MATCH(K9,Management!$B$3:$B$50,0))),"Valid Approval","Limit Exceeded"),"Check Management Name")))
A10: =IF(D10="","",ROW()-1) | L10: =IF(K10="","",IFERROR(INDEX(Management!$A$3:$A$50,MATCH(K10,Management!$B$3:$B$50,0)),"")) | M10: =IF(I10="","",IF(K10="","Select Approval Name",IFERROR(IF(I10<=IF(INDEX(Management!$C$3:$C$50,MATCH(K10,Management!$B$3:$B$50,0))="Unlimited",10^15,INDEX(Management!$C$3:$C$50,MATCH(K10,Management!$B$3:$B$50,0))),"Valid Approval","Limit Exceeded"),"Check Management Name")))
A11: =IF(D11="","",ROW()-1) | L11: =IF(K11="","",IFERROR(INDEX(Management!$A$3:$A$50,MATCH(K11,Management!$B$3:$B$50,0)),"")) | M11: =IF(I11="","",IF(K11="","Select Approval Name",IFERROR(IF(I11<=IF(INDEX(Management!$C$3:$C$50,MATCH(K11,Management!$B$3:$B$50,0))="Unlimited",10^15,INDEX(Management!$C$3:$C$50,MATCH(K11,Management!$B$3:$B$50,0))),"Valid Approval","Limit Exceeded"),"Check Management Name")))
A12: =IF(D12="","",ROW()-1) | L12: =IF(K12="","",IFERROR(INDEX(Management!$A$3:$A$50,MATCH(K12,Management!$B$3:$B$50,0)),"")) | M12: =IF(I12="","",IF(K12="","Select Approval Name",IFERROR(IF(I12<=IF(INDEX(Management!$C$3:$C$50,MATCH(K12,Management!$B$3:$B$50,0))="Unlimited",10^15,INDEX(Management!$C$3:$C$50,MATCH(K12,Management!$B$3:$B$50,0))),"Valid Approval","Limit Exceeded"),"Check Management Name")))
A13: =IF(D13="","",ROW()-1) | L13: =IF(K13="","",IFERROR(INDEX(Management!$A$3:$A$50,MATCH(K13,Management!$B$3:$B$50,0)),"")) | M13: =IF(I13="","",IF(K13="","Select Approval Name",IFERROR(IF(I13<=IF(INDEX(Management!$C$3:$C$50,MATCH(K13,Management!$B$3:$B$50,0))="Unlimited",10^15,INDEX(Management!$C$3:$C$50,MATCH(K13,Management!$B$3:$B$50,0))),"Valid Approval","Limit Exceeded"),"Check Management Name")))
... A201: =IF(D201="","",ROW()-1) | L201: =IF(K201="","",IFERROR(INDEX(Management!$A$3:$A$50,MATCH(K201,Management!$B$3:$B$50,0)),"")) | M201: =IF(I201="","",IF(K201="","Select Approval Name",IFERROR(IF(I201<=IF(INDEX(Management!$C$3:$C$50,MATCH(K201,Management!$B$3:$B$50,0))="Unlimited",10^15,INDEX(Management!$C$3:$C$50,MATCH(K201,Management!$B$3:$B$50,0))),"Valid Approval","Limit Exceeded"),"Check Management Name")))

Sheet 5
A1: S.No. | B1: Customer Name | C1: Contact No | D1: Return Trx | E1: Trx No | F1: Item Description | G1: Item Exp Date | H1: Qty | I1: Total Amount | J1: Reason | K1: Approval Name (Auto) | L1: Designation (Auto) | M1: System Status | N1: Cash/Voucher | O1: Rcv by | P1: CCTV/Time | Q1: Trx Time
A2: =IF(D2="","",ROW()-1) | L2: =IF(K2="","",IFERROR(INDEX(Management!$A$3:$A$50,MATCH(K2,Management!$B$3:$B$50,0)),"")) | M2: =IF(I2="","",IF(K2="","Select Approval Name",IFERROR(IF(I2<=IF(INDEX(Management!$C$3:$C$50,MATCH(K2,Management!$B$3:$B$50,0))="Unlimited",10^15,INDEX(Management!$C$3:$C$50,MATCH(K2,Management!$B$3:$B$50,0))),"Valid Approval","Limit Exceeded"),"Check Management Name")))
A3: =IF(D3="","",ROW()-1) | L3: =IF(K3="","",IFERROR(INDEX(Management!$A$3:$A$50,MATCH(K3,Management!$B$3:$B$50,0)),"")) | M3: =IF(I3="","",IF(K3="","Select Approval Name",IFERROR(IF(I3<=IF(INDEX(Management!$C$3:$C$50,MATCH(K3,Management!$B$3:$B$50,0))="Unlimited",10^15,INDEX(Management!$C$3:$C$50,MATCH(K3,Management!$B$3:$B$50,0))),"Valid Approval","Limit Exceeded"),"Check Management Name")))
A4: =IF(D4="","",ROW()-1) | L4: =IF(K4="","",IFERROR(INDEX(Management!$A$3:$A$50,MATCH(K4,Management!$B$3:$B$50,0)),"")) | M4: =IF(I4="","",IF(K4="","Select Approval Name",IFERROR(IF(I4<=IF(INDEX(Management!$C$3:$C$50,MATCH(K4,Management!$B$3:$B$50,0))="Unlimited",10^15,INDEX(Management!$C$3:$C$50,MATCH(K4,Management!$B$3:$B$50,0))),"Valid Approval","Limit Exceeded"),"Check Management Name")))
A5: =IF(D5="","",ROW()-1) | L5: =IF(K5="","",IFERROR(INDEX(Management!$A$3:$A$50,MATCH(K5,Management!$B$3:$B$50,0)),"")) | M5: =IF(I5="","",IF(K5="","Select Approval Name",IFERROR(IF(I5<=IF(INDEX(Management!$C$3:$C$50,MATCH(K5,Management!$B$3:$B$50,0))="Unlimited",10^15,INDEX(Management!$C$3:$C$50,MATCH(K5,Management!$B$3:$B$50,0))),"Valid Approval","Limit Exceeded"),"Check Management Name")))
A6: =IF(D6="","",ROW()-1) | L6: =IF(K6="","",IFERROR(INDEX(Management!$A$3:$A$50,MATCH(K6,Management!$B$3:$B$50,0)),"")) | M6: =IF(I6="","",IF(K6="","Select Approval Name",IFERROR(IF(I6<=IF(INDEX(Management!$C$3:$C$50,MATCH(K6,Management!$B$3:$B$50,0))="Unlimited",10^15,INDEX(Management!$C$3:$C$50,MATCH(K6,Management!$B$3:$B$50,0))),"Valid Approval","Limit Exceeded"),"Check Management Name")))
A7: =IF(D7="","",ROW()-1) | L7: =IF(K7="","",IFERROR(INDEX(Management!$A$3:$A$50,MATCH(K7,Management!$B$3:$B$50,0)),"")) | M7: =IF(I7="","",IF(K7="","Select Approval Name",IFERROR(IF(I7<=IF(INDEX(Management!$C$3:$C$50,MATCH(K7,Management!$B$3:$B$50,0))="Unlimited",10^15,INDEX(Management!$C$3:$C$50,MATCH(K7,Management!$B$3:$B$50,0))),"Valid Approval","Limit Exceeded"),"Check Management Name")))
A8: =IF(D8="","",ROW()-1) | L8: =IF(K8="","",IFERROR(INDEX(Management!$A$3:$A$50,MATCH(K8,Management!$B$3:$B$50,0)),"")) | M8: =IF(I8="","",IF(K8="","Select Approval Name",IFERROR(IF(I8<=IF(INDEX(Management!$C$3:$C$50,MATCH(K8,Management!$B$3:$B$50,0))="Unlimited",10^15,INDEX(Management!$C$3:$C$50,MATCH(K8,Management!$B$3:$B$50,0))),"Valid Approval","Limit Exceeded"),"Check Management Name")))
A9: =IF(D9="","",ROW()-1) | L9: =IF(K9="","",IFERROR(INDEX(Management!$A$3:$A$50,MATCH(K9,Management!$B$3:$B$50,0)),"")) | M9: =IF(I9="","",IF(K9="","Select Approval Name",IFERROR(IF(I9<=IF(INDEX(Management!$C$3:$C$50,MATCH(K9,Management!$B$3:$B$50,0))="Unlimited",10^15,INDEX(Management!$C$3:$C$50,MATCH(K9,Management!$B$3:$B$50,0))),"Valid Approval","Limit Exceeded"),"Check Management Name")))
A10: =IF(D10="","",ROW()-1) | L10: =IF(K10="","",IFERROR(INDEX(Management!$A$3:$A$50,MATCH(K10,Management!$B$3:$B$50,0)),"")) | M10: =IF(I10="","",IF(K10="","Select Approval Name",IFERROR(IF(I10<=IF(INDEX(Management!$C$3:$C$50,MATCH(K10,Management!$B$3:$B$50,0))="Unlimited",10^15,INDEX(Management!$C$3:$C$50,MATCH(K10,Management!$B$3:$B$50,0))),"Valid Approval","Limit Exceeded"),"Check Management Name")))
A11: =IF(D11="","",ROW()-1) | L11: =IF(K11="","",IFERROR(INDEX(Management!$A$3:$A$50,MATCH(K11,Management!$B$3:$B$50,0)),"")) | M11: =IF(I11="","",IF(K11="","Select Approval Name",IFERROR(IF(I11<=IF(INDEX(Management!$C$3:$C$50,MATCH(K11,Management!$B$3:$B$50,0))="Unlimited",10^15,INDEX(Management!$C$3:$C$50,MATCH(K11,Management!$B$3:$B$50,0))),"Valid Approval","Limit Exceeded"),"Check Management Name")))
A12: =IF(D12="","",ROW()-1) | L12: =IF(K12="","",IFERROR(INDEX(Management!$A$3:$A$50,MATCH(K12,Management!$B$3:$B$50,0)),"")) | M12: =IF(I12="","",IF(K12="","Select Approval Name",IFERROR(IF(I12<=IF(INDEX(Management!$C$3:$C$50,MATCH(K12,Management!$B$3:$B$50,0))="Unlimited",10^15,INDEX(Management!$C$3:$C$50,MATCH(K12,Management!$B$3:$B$50,0))),"Valid Approval","Limit Exceeded"),"Check Management Name")))
A13: =IF(D13="","",ROW()-1) | L13: =IF(K13="","",IFERROR(INDEX(Management!$A$3:$A$50,MATCH(K13,Management!$B$3:$B$50,0)),"")) | M13: =IF(I13="","",IF(K13="","Select Approval Name",IFERROR(IF(I13<=IF(INDEX(Management!$C$3:$C$50,MATCH(K13,Management!$B$3:$B$50,0))="Unlimited",10^15,INDEX(Management!$C$3:$C$50,MATCH(K13,Management!$B$3:$B$50,0))),"Valid Approval","Limit Exceeded"),"Check Management Name")))
... A201: =IF(D201="","",ROW()-1) | L201: =IF(K201="","",IFERROR(INDEX(Management!$A$3:$A$50,MATCH(K201,Management!$B$3:$B$50,0)),"")) | M201: =IF(I201="","",IF(K201="","Select Approval Name",IFERROR(IF(I201<=IF(INDEX(Management!$C$3:$C$50,MATCH(K201,Management!$B$3:$B$50,0))="Unlimited",10^15,INDEX(Management!$C$3:$C$50,MATCH(K201,Management!$B$3:$B$50,0))),"Valid Approval","Limit Exceeded"),"Check Management Name")))

Sheet 6
A1: S.No. | B1: Customer Name | C1: Contact No | D1: Return Trx | E1: Trx No | F1: Item Description | G1: Item Exp Date | H1: Qty | I1: Total Amount | J1: Reason | K1: Approval Name (Auto) | L1: Designation (Auto) | M1: System Status | N1: Cash/Voucher | O1: Rcv by | P1: CCTV/Time | Q1: Trx Time
A2: =IF(D2="","",ROW()-1) | L2: =IF(K2="","",IFERROR(INDEX(Management!$A$3:$A$50,MATCH(K2,Management!$B$3:$B$50,0)),"")) | M2: =IF(I2="","",IF(K2="","Select Approval Name",IFERROR(IF(I2<=IF(INDEX(Management!$C$3:$C$50,MATCH(K2,Management!$B$3:$B$50,0))="Unlimited",10^15,INDEX(Management!$C$3:$C$50,MATCH(K2,Management!$B$3:$B$50,0))),"Valid Approval","Limit Exceeded"),"Check Management Name")))
A3: =IF(D3="","",ROW()-1) | L3: =IF(K3="","",IFERROR(INDEX(Management!$A$3:$A$50,MATCH(K3,Management!$B$3:$B$50,0)),"")) | M3: =IF(I3="","",IF(K3="","Select Approval Name",IFERROR(IF(I3<=IF(INDEX(Management!$C$3:$C$50,MATCH(K3,Management!$B$3:$B$50,0))="Unlimited",10^15,INDEX(Management!$C$3:$C$50,MATCH(K3,Management!$B$3:$B$50,0))),"Valid Approval","Limit Exceeded"),"Check Management Name")))
A4: =IF(D4="","",ROW()-1) | L4: =IF(K4="","",IFERROR(INDEX(Management!$A$3:$A$50,MATCH(K4,Management!$B$3:$B$50,0)),"")) | M4: =IF(I4="","",IF(K4="","Select Approval Name",IFERROR(IF(I4<=IF(INDEX(Management!$C$3:$C$50,MATCH(K4,Management!$B$3:$B$50,0))="Unlimited",10^15,INDEX(Management!$C$3:$C$50,MATCH(K4,Management!$B$3:$B$50,0))),"Valid Approval","Limit Exceeded"),"Check Management Name")))
A5: =IF(D5="","",ROW()-1) | L5: =IF(K5="","",IFERROR(INDEX(Management!$A$3:$A$50,MATCH(K5,Management!$B$3:$B$50,0)),"")) | M5: =IF(I5="","",IF(K5="","Select Approval Name",IFERROR(IF(I5<=IF(INDEX(Management!$C$3:$C$50,MATCH(K5,Management!$B$3:$B$50,0))="Unlimited",10^15,INDEX(Management!$C$3:$C$50,MATCH(K5,Management!$B$3:$B$50,0))),"Valid Approval","Limit Exceeded"),"Check Management Name")))
A6: =IF(D6="","",ROW()-1) | L6: =IF(K6="","",IFERROR(INDEX(Management!$A$3:$A$50,MATCH(K6,Management!$B$3:$B$50,0)),"")) | M6: =IF(I6="","",IF(K6="","Select Approval Name",IFERROR(IF(I6<=IF(INDEX(Management!$C$3:$C$50,MATCH(K6,Management!$B$3:$B$50,0))="Unlimited",10^15,INDEX(Management!$C$3:$C$50,MATCH(K6,Management!$B$3:$B$50,0))),"Valid Approval","Limit Exceeded"),"Check Management Name")))
A7: =IF(D7="","",ROW()-1) | L7: =IF(K7="","",IFERROR(INDEX(Management!$A$3:$A$50,MATCH(K7,Management!$B$3:$B$50,0)),"")) | M7: =IF(I7="","",IF(K7="","Select Approval Name",IFERROR(IF(I7<=IF(INDEX(Management!$C$3:$C$50,MATCH(K7,Management!$B$3:$B$50,0))="Unlimited",10^15,INDEX(Management!$C$3:$C$50,MATCH(K7,Management!$B$3:$B$50,0))),"Valid Approval","Limit Exceeded"),"Check Management Name")))
A8: =IF(D8="","",ROW()-1) | L8: =IF(K8="","",IFERROR(INDEX(Management!$A$3:$A$50,MATCH(K8,Management!$B$3:$B$50,0)),"")) | M8: =IF(I8="","",IF(K8="","Select Approval Name",IFERROR(IF(I8<=IF(INDEX(Management!$C$3:$C$50,MATCH(K8,Management!$B$3:$B$50,0))="Unlimited",10^15,INDEX(Management!$C$3:$C$50,MATCH(K8,Management!$B$3:$B$50,0))),"Valid Approval","Limit Exceeded"),"Check Management Name")))
A9: =IF(D9="","",ROW()-1) | L9: =IF(K9="","",IFERROR(INDEX(Management!$A$3:$A$50,MATCH(K9,Management!$B$3:$B$50,0)),"")) | M9: =IF(I9="","",IF(K9="","Select Approval Name",IFERROR(IF(I9<=IF(INDEX(Management!$C$3:$C$50,MATCH(K9,Management!$B$3:$B$50,0))="Unlimited",10^15,INDEX(Management!$C$3:$C$50,MATCH(K9,Management!$B$3:$B$50,0))),"Valid Approval","Limit Exceeded"),"Check Management Name")))
A10: =IF(D10="","",ROW()-1) | L10: =IF(K10="","",IFERROR(INDEX(Management!$A$3:$A$50,MATCH(K10,Management!$B$3:$B$50,0)),"")) | M10: =IF(I10="","",IF(K10="","Select Approval Name",IFERROR(IF(I10<=IF(INDEX(Management!$C$3:$C$50,MATCH(K10,Management!$B$3:$B$50,0))="Unlimited",10^15,INDEX(Management!$C$3:$C$50,MATCH(K10,Management!$B$3:$B$50,0))),"Valid Approval","Limit Exceeded"),"Check Management Name")))
A11: =IF(D11="","",ROW()-1) | L11: =IF(K11="","",IFERROR(INDEX(Management!$A$3:$A$50,MATCH(K11,Management!$B$3:$B$50,0)),"")) | M11: =IF(I11="","",IF(K11="","Select Approval Name",IFERROR(IF(I11<=IF(INDEX(Management!$C$3:$C$50,MATCH(K11,Management!$B$3:$B$50,0))="Unlimited",10^15,INDEX(Management!$C$3:$C$50,MATCH(K11,Management!$B$3:$B$50,0))),"Valid Approval","Limit Exceeded"),"Check Management Name")))
A12: =IF(D12="","",ROW()-1) | L12: =IF(K12="","",IFERROR(INDEX(Management!$A$3:$A$50,MATCH(K12,Management!$B$3:$B$50,0)),"")) | M12: =IF(I12="","",IF(K12="","Select Approval Name",IFERROR(IF(I12<=IF(INDEX(Management!$C$3:$C$50,MATCH(K12,Management!$B$3:$B$50,0))="Unlimited",10^15,INDEX(Management!$C$3:$C$50,MATCH(K12,Management!$B$3:$B$50,0))),"Valid Approval","Limit Exceeded"),"Check Management Name")))
A13: =IF(D13="","",ROW()-1) | L13: =IF(K13="","",IFERROR(INDEX(Management!$A$3:$A$50,MATCH(K13,Management!$B$3:$B$50,0)),"")) | M13: =IF(I13="","",IF(K13="","Select Approval Name",IFERROR(IF(I13<=IF(INDEX(Management!$C$3:$C$50,MATCH(K13,Management!$B$3:$B$50,0))="Unlimited",10^15,INDEX(Management!$C$3:$C$50,MATCH(K13,Management!$B$3:$B$50,0))),"Valid Approval","Limit Exceeded"),"Check Management Name")))
... A201: =IF(D201="","",ROW()-1) | L201: =IF(K201="","",IFERROR(INDEX(Management!$A$3:$A$50,MATCH(K201,Management!$B$3:$B$50,0)),"")) | M201: =IF(I201="","",IF(K201="","Select Approval Name",IFERROR(IF(I201<=IF(INDEX(Management!$C$3:$C$50,MATCH(K201,Management!$B$3:$B$50,0))="Unlimited",10^15,INDEX(Management!$C$3:$C$50,MATCH(K201,Management!$B$3:$B$50,0))),"Valid Approval","Limit Exceeded"),"Check Management Name")))

Sheet 7
A1: S.No. | B1: Customer Name | C1: Contact No | D1: Return Trx | E1: Trx No | F1: Item Description | G1: Item Exp Date | H1: Qty | I1: Total Amount | J1: Reason | K1: Approval Name (Auto) | L1: Designation (Auto) | M1: System Status | N1: Cash/Voucher | O1: Rcv by | P1: CCTV/Time | Q1: Trx Time
A2: =IF(D2="","",ROW()-1) | L2: =IF(K2="","",IFERROR(INDEX(Management!$A$3:$A$50,MATCH(K2,Management!$B$3:$B$50,0)),"")) | M2: =IF(I2="","",IF(K2="","Select Approval Name",IFERROR(IF(I2<=IF(INDEX(Management!$C$3:$C$50,MATCH(K2,Management!$B$3:$B$50,0))="Unlimited",10^15,INDEX(Management!$C$3:$C$50,MATCH(K2,Management!$B$3:$B$50,0))),"Valid Approval","Limit Exceeded"),"Check Management Name")))
A3: =IF(D3="","",ROW()-1) | L3: =IF(K3="","",IFERROR(INDEX(Management!$A$3:$A$50,MATCH(K3,Management!$B$3:$B$50,0)),"")) | M3: =IF(I3="","",IF(K3="","Select Approval Name",IFERROR(IF(I3<=IF(INDEX(Management!$C$3:$C$50,MATCH(K3,Management!$B$3:$B$50,0))="Unlimited",10^15,INDEX(Management!$C$3:$C$50,MATCH(K3,Management!$B$3:$B$50,0))),"Valid Approval","Limit Exceeded"),"Check Management Name")))
A4: =IF(D4="","",ROW()-1) | L4: =IF(K4="","",IFERROR(INDEX(Management!$A$3:$A$50,MATCH(K4,Management!$B$3:$B$50,0)),"")) | M4: =IF(I4="","",IF(K4="","Select Approval Name",IFERROR(IF(I4<=IF(INDEX(Management!$C$3:$C$50,MATCH(K4,Management!$B$3:$B$50,0))="Unlimited",10^15,INDEX(Management!$C$3:$C$50,MATCH(K4,Management!$B$3:$B$50,0))),"Valid Approval","Limit Exceeded"),"Check Management Name")))
A5: =IF(D5="","",ROW()-1) | L5: =IF(K5="","",IFERROR(INDEX(Management!$A$3:$A$50,MATCH(K5,Management!$B$3:$B$50,0)),"")) | M5: =IF(I5="","",IF(K5="","Select Approval Name",IFERROR(IF(I5<=IF(INDEX(Management!$C$3:$C$50,MATCH(K5,Management!$B$3:$B$50,0))="Unlimited",10^15,INDEX(Management!$C$3:$C$50,MATCH(K5,Management!$B$3:$B$50,0))),"Valid Approval","Limit Exceeded"),"Check Management Name")))
A6: =IF(D6="","",ROW()-1) | L6: =IF(K6="","",IFERROR(INDEX(Management!$A$3:$A$50,MATCH(K6,Management!$B$3:$B$50,0)),"")) | M6: =IF(I6="","",IF(K6="","Select Approval Name",IFERROR(IF(I6<=IF(INDEX(Management!$C$3:$C$50,MATCH(K6,Management!$B$3:$B$50,0))="Unlimited",10^15,INDEX(Management!$C$3:$C$50,MATCH(K6,Management!$B$3:$B$50,0))),"Valid Approval","Limit Exceeded"),"Check Management Name")))
A7: =IF(D7="","",ROW()-1) | L7: =IF(K7="","",IFERROR(INDEX(Management!$A$3:$A$50,MATCH(K7,Management!$B$3:$B$50,0)),"")) | M7: =IF(I7="","",IF(K7="","Select Approval Name",IFERROR(IF(I7<=IF(INDEX(Management!$C$3:$C$50,MATCH(K7,Management!$B$3:$B$50,0))="Unlimited",10^15,INDEX(Management!$C$3:$C$50,MATCH(K7,Management!$B$3:$B$50,0))),"Valid Approval","Limit Exceeded"),"Check Management Name")))
A8: =IF(D8="","",ROW()-1) | L8: =IF(K8="","",IFERROR(INDEX(Management!$A$3:$A$50,MATCH(K8,Management!$B$3:$B$50,0)),"")) | M8: =IF(I8="","",IF(K8="","Select Approval Name",IFERROR(IF(I8<=IF(INDEX(Management!$C$3:$C$50,MATCH(K8,Management!$B$3:$B$50,0))="Unlimited",10^15,INDEX(Management!$C$3:$C$50,MATCH(K8,Management!$B$3:$B$50,0))),"Valid Approval","Limit Exceeded"),"Check Management Name")))
A9: =IF(D9="","",ROW()-1) | L9: =IF(K9="","",IFERROR(INDEX(Management!$A$3:$A$50,MATCH(K9,Management!$B$3:$B$50,0)),"")) | M9: =IF(I9="","",IF(K9="","Select Approval Name",IFERROR(IF(I9<=IF(INDEX(Management!$C$3:$C$50,MATCH(K9,Management!$B$3:$B$50,0))="Unlimited",10^15,INDEX(Management!$C$3:$C$50,MATCH(K9,Management!$B$3:$B$50,0))),"Valid Approval","Limit Exceeded"),"Check Management Name")))
A10: =IF(D10="","",ROW()-1) | L10: =IF(K10="","",IFERROR(INDEX(Management!$A$3:$A$50,MATCH(K10,Management!$B$3:$B$50,0)),"")) | M10: =IF(I10="","",IF(K10="","Select Approval Name",IFERROR(IF(I10<=IF(INDEX(Management!$C$3:$C$50,MATCH(K10,Management!$B$3:$B$50,0))="Unlimited",10^15,INDEX(Management!$C$3:$C$50,MATCH(K10,Management!$B$3:$B$50,0))),"Valid Approval","Limit Exceeded"),"Check Management Name")))
A11: =IF(D11="","",ROW()-1) | L11: =IF(K11="","",IFERROR(INDEX(Management!$A$3:$A$50,MATCH(K11,Management!$B$3:$B$50,0)),"")) | M11: =IF(I11="","",IF(K11="","Select Approval Name",IFERROR(IF(I11<=IF(INDEX(Management!$C$3:$C$50,MATCH(K11,Management!$B$3:$B$50,0))="Unlimited",10^15,INDEX(Management!$C$3:$C$50,MATCH(K11,Management!$B$3:$B$50,0))),"Valid Approval","Limit Exceeded"),"Check Management Name")))
A12: =IF(D12="","",ROW()-1) | L12: =IF(K12="","",IFERROR(INDEX(Management!$A$3:$A$50,MATCH(K12,Management!$B$3:$B$50,0)),"")) | M12: =IF(I12="","",IF(K12="","Select Approval Name",IFERROR(IF(I12<=IF(INDEX(Management!$C$3:$C$50,MATCH(K12,Management!$B$3:$B$50,0))="Unlimited",10^15,INDEX(Management!$C$3:$C$50,MATCH(K12,Management!$B$3:$B$50,0))),"Valid Approval","Limit Exceeded"),"Check Management Name")))
A13: =IF(D13="","",ROW()-1) | L13: =IF(K13="","",IFERROR(INDEX(Management!$A$3:$A$50,MATCH(K13,Management!$B$3:$B$50,0)),"")) | M13: =IF(I13="","",IF(K13="","Select Approval Name",IFERROR(IF(I13<=IF(INDEX(Management!$C$3:$C$50,MATCH(K13,Management!$B$3:$B$50,0))="Unlimited",10^15,INDEX(Management!$C$3:$C$50,MATCH(K13,Management!$B$3:$B$50,0))),"Valid Approval","Limit Exceeded"),"Check Management Name")))
